File: RAMAN/MoS2_BM_UP/MoS2-2_1H (3).txt
#Acq. time (s)=	15
#Accumulations=	3
#Range (cm-¹)=	200...1200
#Windows=	1
#Auto scanning=	Off
#Autofocus=	Off
#AutoExposure=	Off
#Spike filter=	Multiple accum.
#Delay time (s)=	0
#Binning=	1
#Readout mode=	Signal
#DeNoise=	Off
#ICS correction=	Off
#Dark correction=	Off
#Inst. Process=	Off
#Detector Gain=	Best Dynamic Range
#Detector ADC=	45 kHz
#Detector temperature (°C)=	-60,1
#Instrument=	XploRA Plus
#Detector=	Syncerity OE
#Objective=	x50_VIS_LWD
#Grating=	2400 (400nm)
#Filter=	1%
#Laser=	532nm_Edge
#Slit (µm)=	50
#Hole (µm)=	100
#Temperature=	0
#Laser pol=	Circular
#Raman pol=	None
#StageXY=	75x50mm Scan+
#StageZ=	Z motor
#X (µm)=	0
#Y (µm)=	0
#Z (µm)=	402,55
#Full time(s)=	52
#Project=	A
#Sample=	B
#Site=	C
#Title=	D
#Remark=
#Date=	27.09.2024 13:58
#Acquired=	27.09.2024 13:58:53
#AxisType[0]=Intens
#AxisUnit[0]=Cnt
#AxisType[1]=Spectr
#AxisUnit[1]=1/cm
202,268	42
203,409	42
204,547	42
205,687	36
206,825	40
207,965	42
209,103	40
210,241	44
211,378	41
212,516	45
213,653	45
214,79	43
215,927	40
217,064	46
218,2	40
219,337	38
220,471	44
221,607	51
222,743	41
223,877	40
225,011	34
226,146	42
227,28	40
228,413	41
229,548	42
230,681	46
231,814	40
232,947	40
234,08	42
235,21	44
236,342	40
237,475	41
238,607	36
239,736	37
240,868	43
241,998	37
243,129	44
244,258	40
245,39	36
246,519	35
247,647	37
248,776	40
249,905	46
251,033	41
252,161	39
253,29	38
254,418	42
255,543	45
256,671	40
257,799	38
258,924	44
260,051	41
261,177	42
262,304	40
263,428	46
264,553	36
265,678	38
266,802	40
267,926	42
269,05	35
270,174	34
271,298	39
272,422	40
273,546	40
274,667	36
275,79	42
276,914	40
278,035	38
279,157	28
280,278	41
281,399	46
282,519	42
283,641	48
284,762	42
285,882	54
287,001	52
288,121	46
289,239	42
290,358	36
291,478	43
292,597	37
293,714	44
294,833	38
295,949	38
297,068	37
298,184	44
299,301	37
300,417	38
301,533	36
302,651	38
303,767	40
304,88	44
305,996	41
307,111	34
308,226	37
309,341	36
310,454	42
311,569	38
312,682	40
313,796	38
314,909	38
316,021	38
317,135	34
318,247	44
319,359	37
320,47	43
321,582	38
322,693	48
323,804	46
324,913	42
326,024	42
327,135	40
328,244	40
329,355	36
330,463	44
331,573	42
332,681	36
333,789	45
334,899	42
336,007	42
337,115	43
338,222	46
339,329	36
340,437	38
341,542	42
342,648	52
343,755	48
344,86	43
345,966	48
347,071	52
348,177	44
349,281	50
350,385	47
351,491	40
352,594	43
353,698	44
354,801	44
355,904	51
357,008	44
358,109	50
359,211	50
360,314	39
361,415	51
362,517	44
363,619	53
364,72	54
365,82	52
366,921	52
368,021	50
369,121	53
370,22	59
371,32	55
372,419	50
373,518	66
374,617	74
375,714	84
376,812	106
377,911	151
379,007	197
380,105	222
381,202	230
382,297	250
383,395	177
384,491	116
385,587	78
386,682	52
387,777	58
388,873	59
389,968	62
391,063	55
392,157	58
393,25	52
394,344	69
395,437	62
396,531	71
397,623	82
398,717	88
399,809	108
400,901	124
401,992	177
403,084	204
404,175	318
405,266	422
406,357	494
407,448	519
408,539	418
409,627	244
410,718	156
411,806	106
412,896	86
413,984	68
415,074	68
416,162	60
417,25	62
418,338	55
419,425	60
420,512	60
421,599	58
422,686	57
423,773	58
424,858	54
425,945	63
427,031	58
428,116	54
429,202	54
430,286	52
431,37	50
432,456	55
433,539	60
434,623	60
435,706	63
436,79	60
437,873	63
438,954	57
440,037	56
441,12	64
442,202	64
443,283	63
444,365	69
445,445	61
446,526	65
447,608	70
448,688	81
449,767	71
450,847	71
451,926	70
453,006	56
454,085	68
455,162	71
456,241	62
457,32	67
458,396	65
459,475	58
460,551	66
461,63	60
462,706	68
463,782	60
464,858	60
465,934	46
467,009	56
468,085	46
469,16	47
470,235	40
471,311	40
472,386	41
473,458	37
474,533	42
475,606	40
476,68	46
477,753	38
478,825	39
479,897	41
480,969	42
482,041	41
483,112	36
484,184	40
485,255	41
486,327	41
487,398	42
488,467	38
489,538	36
490,607	44
491,678	48
492,746	30
493,814	40
494,883	41
495,951	38
497,021	41
498,089	42
499,155	42
500,222	40
501,29	36
502,357	42
503,423	39
504,49	42
505,555	39
506,622	44
507,686	40
508,751	38
509,818	38
510,882	38
511,946	44
513,01	39
514,074	42
515,138	38
516,2	40
517,264	48
518,327	36
519,389	40
520,452	43
521,513	36
522,574	37
523,637	40
524,698	45
525,758	40
526,819	40
527,879	42
528,939	40
529,999	40
531,059	40
532,117	42
533,177	40
534,235	42
535,294	40
536,352	43
537,411	44
538,468	40
539,525	39
540,582	41
541,638	48
542,695	44
543,752	40
544,808	46
545,864	42
546,92	45
547,974	50
549,03	45
550,084	46
551,14	41
552,193	41
553,246	44
554,3	49
555,353	45
556,406	40
557,459	40
558,511	48
559,564	45
560,617	49
561,669	48
562,719	44
563,771	51
564,821	54
565,871	52
566,923	50
567,973	42
569,022	55
570,072	49
571,121	44
572,17	47
573,219	50
574,268	50
575,317	42
576,363	48
577,412	52
578,458	52
579,507	54
580,553	48
581,599	45
582,647	55
583,693	50
584,738	59
585,784	50
586,829	47
587,873	50
588,918	55
589,963	56
591,008	48
592,051	48
593,096	49
594,138	40
595,181	52
596,225	53
597,267	50
598,309	49
599,351	46
600,393	42
601,435	48
602,475	43
603,516	52
604,557	47
605,597	48
606,638	43
607,677	42
608,718	44
609,757	44
610,795	45
611,834	46
612,872	42
613,91	39
614,949	42
615,987	45
617,025	45
618,063	36
619,098	46
620,136	48
621,171	43
622,209	38
623,244	45
624,279	44
625,314	42
626,349	45
627,384	45
628,418	40
629,453	44
630,487	42
631,521	40
632,554	36
633,588	46
634,62	41
635,653	45
636,685	42
637,717	40
638,748	39
639,781	38
640,813	42
641,844	40
642,873	41
643,904	38
644,934	34
645,965	35
646,993	42
648,024	38
649,052	36
650,08	33
651,11	40
652,138	36
653,166	40
654,194	32
655,221	38
656,249	34
657,276	41
658,303	35
659,328	35
660,355	40
661,38	39
662,407	39
663,432	34
664,456	36
665,482	43
666,507	34
667,531	36
668,555	34
669,579	41
670,603	34
671,625	35
672,648	34
673,672	40
674,693	37
675,716	38
676,737	39
677,758	39
678,779	33
679,802	38
680,823	43
681,843	40
682,862	37
683,882	36
684,902	36
685,922	41
686,94	40
687,96	40
688,978	35
689,997	32
691,015	40
692,032	33
693,05	35
694,067	38
695,084	32
696,101	34
697,118	40
698,134	34
699,149	32
700,166	40
701,182	40
702,196	34
703,21	34
704,226	38
705,24	38
706,254	35
707,268	38
708,281	30
709,295	38
710,308	40
711,319	37
712,333	42
713,346	38
714,357	38
715,369	41
716,38	38
717,391	46
718,401	40
719,413	40
720,424	44
721,434	40
722,442	43
723,452	42
724,461	42
725,471	34
726,479	42
727,488	38
728,495	42
729,503	37
730,512	44
731,519	41
732,526	44
733,532	46
734,539	49
735,546	38
736,552	46
737,556	45
738,563	44
739,567	45
740,573	42
741,577	41
742,582	44
743,586	44
744,589	49
745,593	46
746,596	44
747,599	45
748,603	40
749,606	47
750,607	46
751,609	42
752,61	44
753,612	46
754,613	45
755,613	30
756,616	48
757,616	44
758,616	41
759,616	43
760,615	42
761,613	42
762,613	41
763,612	45
764,609	39
765,609	38
766,606	40
767,605	36
768,602	43
769,599	36
770,595	40
771,592	39
772,588	44
773,585	42
774,581	36
775,575	41
776,571	39
777,565	37
778,561	38
779,555	42
780,548	48
781,544	45
782,537	44
783,53	42
784,524	42
785,517	40
786,51	38
787,5	40
788,493	40
789,484	40
790,476	34
791,467	40
792,459	36
793,449	39
794,44	39
795,43	38
796,419	37
797,409	31
798,399	38
799,388	38
800,376	37
801,365	40
802,353	35
803,342	39
804,329	37
805,316	41
806,304	38
807,291	41
808,278	40
809,264	42
810,251	36
811,235	40
812,221	36
813,207	45
814,191	38
815,177	34
816,161	39
817,145	39
818,13	37
819,114	32
820,097	39
821,08	36
822,063	38
823,044	40
824,027	36
825,01	37
825,991	43
826,973	38
827,954	40
828,936	35
829,917	32
830,897	33
831,877	35
832,857	38
833,837	36
834,817	38
835,794	38
836,774	33
837,753	38
838,731	35
839,71	35
840,687	36
841,664	38
842,641	37
843,618	42
844,595	36
845,571	41
846,548	37
847,524	34
848,5	30
849,475	36
850,451	33
851,425	33
852,401	36
853,375	38
854,348	20
855,322	30
856,295	38
857,269	32
858,242	33
859,215	36
860,186	36
861,159	38
862,13	37
863,103	36
864,074	36
865,044	38
866,017	36
866,987	37
867,957	37
868,928	34
869,898	37
870,866	30
871,835	37
872,805	31
873,773	34
874,742	34
875,71	35
876,677	34
877,645	36
878,612	38
879,579	30
880,546	36
881,513	36
882,479	37
883,446	37
884,411	34
885,377	40
886,341	29
887,308	34
888,272	34
889,236	38
890,2	36
891,164	37
892,127	36
893,091	30
894,055	34
895,016	35
895,979	35
896,941	41
897,904	34
898,865	32
899,826	40
900,789	45
901,749	32
902,71	36
903,671	37
904,631	36
905,589	38
906,55	34
907,51	33
908,468	36
909,426	44
910,386	34
911,344	39
912,301	38
913,259	43
914,216	35
915,174	42
916,131	34
917,088	34
918,043	32
919	34
919,955	36
920,912	30
921,866	34
922,821	37
923,776	41
924,732	36
925,684	36
926,638	33
927,593	34
928,547	34
929,5	32
930,452	38
931,406	34
932,358	39
933,309	36
934,261	38
935,214	37
936,165	42
937,116	38
938,065	36
939,016	35
939,967	30
940,916	38
941,866	35
942,815	36
943,765	32
944,714	39
945,662	33
946,61	34
947,558	34
948,506	30
949,454	34
950,402	30
951,348	36
952,295	35
953,243	34
954,188	32
955,133	38
956,081	37
957,026	32
957,971	32
958,916	35
959,861	39
960,803	37
961,748	32
962,693	33
963,635	34
964,579	34
965,522	34
966,464	35
967,408	36
968,35	30
969,292	34
970,233	38
971,175	38
972,115	34
973,056	34
973,998	41
974,937	30
975,878	28
976,817	34
977,756	35
978,695	33
979,634	34
980,573	34
981,512	39
982,45	38
983,389	32
984,325	30
985,263	33
986,2	34
987,138	31
988,074	41
989,01	36
989,946	39
990,881	34
991,817	32
992,752	34
993,688	34
994,623	38
995,557	36
996,492	34
997,425	32
998,36	39
999,293	34
1000,23	34
1001,16	31
1002,09	37
1003,02	34
1003,96	36
1004,89	32
1005,82	38
1006,75	34
1007,68	40
1008,61	36
1009,54	36
1010,47	28
1011,4	35
1012,33	31
1013,26	36
1014,19	34
1015,12	30
1016,05	33
1016,98	34
1017,9	39
1018,83	37
1019,76	37
1020,69	34
1021,61	30
1022,54	32
1023,47	31
1024,39	36
1025,32	34
1026,25	36
1027,17	32
1028,1	39
1029,02	34
1029,95	33
1030,87	33
1031,79	38
1032,72	36
1033,64	36
1034,56	33
1035,49	37
1036,41	38
1037,33	34
1038,25	35
1039,18	34
1040,1	34
1041,02	32
1041,94	33
1042,86	34
1043,78	34
1044,7	36
1045,62	34
1046,54	34
1047,46	36
1048,38	33
1049,3	30
1050,22	31
1051,14	34
1052,05	34
1052,97	37
1053,89	35
1054,81	35
1055,72	38
1056,64	30
1057,56	36
1058,47	39
1059,39	35
1060,31	26
1061,22	36
1062,14	26
1063,05	34
1063,97	35
1064,88	35
1065,8	32
1066,71	35
1067,62	33
1068,54	28
1069,45	36
1070,36	33
1071,28	34
1072,19	31
1073,1	40
1074,01	38
1074,92	33
1075,83	33
1076,75	39
1077,66	37
1078,57	34
1079,48	30
1080,39	36
1081,3	34
1082,21	32
1083,12	37
1084,02	37
1084,93	32
1085,84	35
1086,75	33
1087,66	28
1088,56	36
1089,47	39
1090,38	34
1091,29	32
1092,19	36
1093,1	35
1094	37
1094,91	34
1095,81	41
1096,72	36
1097,63	32
1098,53	38
1099,43	37
1100,34	30
1101,24	38
1102,15	37
1103,05	34
1103,95	32
1104,85	35
1105,76	28
1106,66	32
1107,56	30
1108,46	33
1109,36	38
1110,27	34
1111,17	31
1112,07	33
1112,97	32
1113,87	36
1114,77	34
1115,67	38
1116,57	30
1117,46	38
1118,36	33
1119,26	36
1120,16	31
1121,06	34
1121,96	33
1122,85	38
1123,75	38
1124,65	35
1125,55	38
1126,44	34
1127,34	33
1128,23	32
1129,13	38
1130,02	30
1130,92	38
1131,81	34
1132,71	38
1133,6	37
1134,5	39
1135,39	37
1136,28	30
1137,18	42
1138,07	31
1138,96	40
1139,85	39
1140,75	37
1141,64	36
1142,53	34
1143,42	38
1144,31	34
1145,2	36
1146,1	32
1146,98	24
1147,88	35
1148,76	41
1149,65	34
1150,54	32
1151,43	32
1152,32	36
1153,21	37
1154,1	38
1154,98	34
1155,87	31
1156,76	34
1157,65	34
1158,54	32
1159,42	31
1160,31	30
1161,19	31
1162,08	36
1162,97	38
1163,85	26
1164,73	35
1165,62	30
1166,5	37
1167,39	30
1168,27	34
1169,16	36
1170,04	30
1170,92	36
1171,81	40
1172,69	35
1173,57	38
1174,45	36
1175,33	39
1176,21	30
1177,1	36
1177,98	38
1178,86	34
1179,74	31
1180,62	38
1181,5	40
1182,38	40
1183,26	36
1184,14	36
1185,02	32
1185,89	35
1186,77	32
1187,65	41
1188,53	33
1189,41	36
1190,28	32
1191,16	36
1192,04	41
1192,91	34
1193,79	35
1194,67	38
1195,54	38
1196,42	35
1197,29	34
1198,17	36
1199,04	34
1199,92	38