File: RAMAN/MoS2_BM_UP/MoS2-5H (3).txt
#Acq. time (s)=	15
#Accumulations=	3
#Range (cm-¹)=	200...1200
#Windows=	1
#Auto scanning=	Off
#Autofocus=	Off
#AutoExposure=	Off
#Spike filter=	Multiple accum.
#Delay time (s)=	0
#Binning=	1
#Readout mode=	Signal
#DeNoise=	Off
#ICS correction=	Off
#Dark correction=	Off
#Inst. Process=	Off
#Detector Gain=	Best Dynamic Range
#Detector ADC=	45 kHz
#Detector temperature (°C)=	-60,1
#Instrument=	XploRA Plus
#Detector=	Syncerity OE
#Objective=	x50_VIS_LWD
#Grating=	2400 (400nm)
#Filter=	1%
#Laser=	532nm_Edge
#Slit (µm)=	50
#Hole (µm)=	100
#Temperature=	0
#Laser pol=	Circular
#Raman pol=	None
#StageXY=	75x50mm Scan+
#StageZ=	Z motor
#X (µm)=	0
#Y (µm)=	0
#Z (µm)=	310,95
#Full time(s)=	52
#Project=	A
#Sample=	B
#Site=	C
#Title=	D
#Remark=
#Date=	27.09.2024 13:18
#Acquired=	27.09.2024 13:18:06
#AxisType[0]=Intens
#AxisUnit[0]=Cnt
#AxisType[1]=Spectr
#AxisUnit[1]=1/cm
202,268	44
203,409	39
204,547	37
205,687	43
206,825	46
207,965	46
209,103	42
210,241	46
211,378	49
212,516	45
213,653	41
214,79	38
215,927	51
217,064	41
218,2	53
219,337	47
220,471	46
221,607	44
222,743	45
223,877	49
225,011	40
226,146	40
227,28	46
228,413	47
229,548	47
230,681	42
231,814	40
232,947	42
234,08	44
235,21	37
236,342	37
237,475	42
238,607	46
239,736	43
240,868	38
241,998	42
243,129	45
244,258	36
245,39	37
246,519	45
247,647	39
248,776	44
249,905	43
251,033	32
252,161	42
253,29	42
254,418	40
255,543	42
256,671	34
257,799	36
258,924	38
260,051	38
261,177	38
262,304	40
263,428	42
264,553	43
265,678	38
266,802	40
267,926	34
269,05	40
270,174	39
271,298	39
272,422	43
273,546	36
274,667	34
275,79	37
276,914	36
278,035	38
279,157	36
280,278	36
281,399	38
282,519	43
283,641	48
284,762	60
285,882	56
287,001	64
288,121	52
289,239	42
290,358	40
291,478	41
292,597	43
293,714	43
294,833	44
295,949	36
297,068	38
298,184	41
299,301	40
300,417	36
301,533	44
302,651	40
303,767	41
304,88	42
305,996	34
307,111	41
308,226	44
309,341	42
310,454	40
311,569	40
312,682	43
313,796	46
314,909	43
316,021	36
317,135	44
318,247	42
319,359	42
320,47	42
321,582	42
322,693	48
323,804	40
324,913	38
326,024	40
327,135	45
328,244	40
329,355	46
330,463	49
331,573	42
332,681	52
333,789	46
334,899	43
336,007	49
337,115	37
338,222	40
339,329	48
340,437	44
341,542	44
342,648	50
343,755	52
344,86	48
345,966	48
347,071	47
348,177	46
349,281	47
350,385	44
351,491	52
352,594	40
353,698	41
354,801	44
355,904	49
357,008	40
358,109	56
359,211	45
360,314	47
361,415	50
362,517	42
363,619	50
364,72	49
365,82	46
366,921	61
368,021	60
369,121	52
370,22	59
371,32	64
372,419	56
373,518	62
374,617	68
375,714	82
376,812	88
377,911	121
379,007	161
380,105	245
381,202	340
382,297	309
383,395	261
384,491	176
385,587	113
386,682	74
387,777	60
388,873	62
389,968	62
391,063	62
392,157	61
393,25	61
394,344	60
395,437	54
396,531	66
397,623	68
398,717	80
399,809	88
400,901	100
401,992	130
403,084	164
404,175	245
405,266	381
406,357	561
407,448	645
408,539	570
409,627	382
410,718	219
411,806	138
412,896	96
413,984	86
415,074	74
416,162	74
417,25	68
418,338	67
419,425	63
420,512	68
421,599	61
422,686	59
423,773	64
424,858	57
425,945	62
427,031	65
428,116	52
429,202	56
430,286	55
431,37	54
432,456	66
433,539	63
434,623	62
435,706	63
436,79	58
437,873	62
438,954	63
440,037	56
441,12	62
442,202	64
443,283	59
444,365	66
445,445	64
446,526	69
447,608	66
448,688	82
449,767	68
450,847	66
451,926	74
453,006	70
454,085	68
455,162	67
456,241	69
457,32	66
458,396	58
459,475	66
460,551	61
461,63	63
462,706	60
463,782	60
464,858	58
465,934	58
467,009	58
468,085	57
469,16	56
470,235	47
471,311	46
472,386	40
473,458	48
474,533	42
475,606	41
476,68	39
477,753	43
478,825	38
479,897	36
480,969	41
482,041	35
483,112	46
484,184	32
485,255	38
486,327	38
487,398	36
488,467	32
489,538	44
490,607	40
491,678	40
492,746	36
493,814	40
494,883	39
495,951	43
497,021	45
498,089	37
499,155	52
500,222	38
501,29	37
502,357	32
503,423	40
504,49	40
505,555	42
506,622	34
507,686	42
508,751	41
509,818	40
510,882	42
511,946	36
513,01	48
514,074	37
515,138	44
516,2	40
517,264	36
518,327	42
519,389	37
520,452	46
521,513	42
522,574	44
523,637	38
524,698	36
525,758	43
526,819	43
527,879	43
528,939	45
529,999	49
531,059	38
532,117	38
533,177	44
534,235	38
535,294	38
536,352	39
537,411	42
538,468	45
539,525	41
540,582	40
541,638	45
542,695	38
543,752	40
544,808	40
545,864	38
546,92	48
547,974	50
549,03	42
550,084	42
551,14	42
552,193	41
553,246	38
554,3	44
555,353	47
556,406	44
557,459	41
558,511	46
559,564	44
560,617	49
561,669	50
562,719	56
563,771	50
564,821	54
565,871	51
566,923	51
567,973	56
569,022	44
570,072	52
571,121	52
572,17	48
573,219	50
574,268	50
575,317	48
576,363	44
577,412	46
578,458	50
579,507	44
580,553	49
581,599	51
582,647	48
583,693	57
584,738	52
585,784	54
586,829	52
587,873	51
588,918	48
589,963	54
591,008	49
592,051	49
593,096	54
594,138	57
595,181	54
596,225	55
597,267	52
598,309	54
599,351	49
600,393	40
601,435	53
602,475	42
603,516	49
604,557	48
605,597	53
606,638	46
607,677	50
608,718	38
609,757	46
610,795	44
611,834	43
612,872	42
613,91	47
614,949	48
615,987	36
617,025	42
618,063	46
619,098	46
620,136	46
621,171	42
622,209	37
623,244	44
624,279	45
625,314	47
626,349	43
627,384	38
628,418	46
629,453	40
630,487	39
631,521	40
632,554	38
633,588	44
634,62	41
635,653	38
636,685	42
637,717	38
638,748	43
639,781	41
640,813	42
641,844	44
642,873	36
643,904	37
644,934	42
645,965	30
646,993	35
648,024	34
649,052	40
650,08	36
651,11	36
652,138	36
653,166	44
654,194	35
655,221	36
656,249	30
657,276	34
658,303	40
659,328	34
660,355	38
661,38	34
662,407	35
663,432	40
664,456	32
665,482	38
666,507	32
667,531	30
668,555	39
669,579	39
670,603	36
671,625	31
672,648	38
673,672	40
674,693	40
675,716	40
676,737	36
677,758	35
678,779	40
679,802	37
680,823	38
681,843	32
682,862	36
683,882	32
684,902	39
685,922	36
686,94	36
687,96	36
688,978	38
689,997	36
691,015	37
692,032	30
693,05	36
694,067	34
695,084	36
696,101	38
697,118	40
698,134	40
699,149	42
700,166	35
701,182	39
702,196	38
703,21	38
704,226	41
705,24	39
706,254	36
707,268	37
708,281	40
709,295	36
710,308	39
711,319	37
712,333	35
713,346	38
714,357	37
715,369	43
716,38	42
717,391	38
718,401	39
719,413	37
720,424	36
721,434	39
722,442	39
723,452	42
724,461	32
725,471	42
726,479	40
727,488	40
728,495	41
729,503	38
730,512	45
731,519	42
732,526	48
733,532	44
734,539	40
735,546	40
736,552	38
737,556	44
738,563	39
739,567	40
740,573	43
741,577	44
742,582	44
743,586	46
744,589	39
745,593	41
746,596	42
747,599	38
748,603	44
749,606	46
750,607	44
751,609	40
752,61	42
753,612	45
754,613	46
755,613	44
756,616	50
757,616	48
758,616	50
759,616	42
760,615	43
761,613	42
762,613	42
763,612	43
764,609	32
765,609	44
766,606	40
767,605	36
768,602	42
769,599	35
770,595	39
771,592	39
772,588	40
773,585	42
774,581	42
775,575	41
776,571	38
777,565	38
778,561	41
779,555	41
780,548	47
781,544	34
782,537	43
783,53	40
784,524	38
785,517	44
786,51	43
787,5	44
788,493	43
789,484	32
790,476	40
791,467	39
792,459	35
793,449	39
794,44	38
795,43	37
796,419	40
797,409	38
798,399	36
799,388	36
800,376	30
801,365	38
802,353	38
803,342	37
804,329	32
805,316	37
806,304	47
807,291	44
808,278	38
809,264	42
810,251	38
811,235	46
812,221	36
813,207	40
814,191	42
815,177	38
816,161	44
817,145	42
818,13	43
819,114	46
820,097	36
821,08	40
822,063	34
823,044	37
824,027	40
825,01	30
825,991	46
826,973	37
827,954	39
828,936	42
829,917	39
830,897	40
831,877	34
832,857	40
833,837	26
834,817	37
835,794	34
836,774	36
837,753	36
838,731	37
839,71	33
840,687	37
841,664	28
842,641	40
843,618	40
844,595	40
845,571	36
846,548	32
847,524	38
848,5	35
849,475	34
850,451	36
851,425	38
852,401	30
853,375	38
854,348	39
855,322	39
856,295	36
857,269	38
858,242	37
859,215	37
860,186	35
861,159	35
862,13	34
863,103	34
864,074	37
865,044	36
866,017	37
866,987	34
867,957	39
868,928	35
869,898	32
870,866	39
871,835	37
872,805	36
873,773	32
874,742	36
875,71	36
876,677	36
877,645	36
878,612	36
879,579	31
880,546	41
881,513	37
882,479	30
883,446	38
884,411	34
885,377	32
886,341	30
887,308	36
888,272	36
889,236	31
890,2	38
891,164	32
892,127	32
893,091	36
894,055	44
895,016	37
895,979	35
896,941	36
897,904	34
898,865	33
899,826	37
900,789	44
901,749	41
902,71	38
903,671	37
904,631	38
905,589	44
906,55	37
907,51	30
908,468	37
909,426	38
910,386	36
911,344	32
912,301	32
913,259	33
914,216	33
915,174	36
916,131	32
917,088	32
918,043	35
919	28
919,955	36
920,912	37
921,866	38
922,821	38
923,776	29
924,732	37
925,684	32
926,638	38
927,593	33
928,547	38
929,5	33
930,452	32
931,406	36
932,358	35
933,309	40
934,261	28
935,214	36
936,165	42
937,116	38
938,065	32
939,016	35
939,967	34
940,916	36
941,866	34
942,815	33
943,765	36
944,714	32
945,662	33
946,61	34
947,558	36
948,506	34
949,454	28
950,402	32
951,348	35
952,295	38
953,243	34
954,188	32
955,133	36
956,081	35
957,026	33
957,971	36
958,916	32
959,861	38
960,803	39
961,748	32
962,693	35
963,635	38
964,579	33
965,522	36
966,464	33
967,408	35
968,35	37
969,292	29
970,233	35
971,175	35
972,115	36
973,056	37
973,998	38
974,937	30
975,878	36
976,817	35
977,756	44
978,695	34
979,634	36
980,573	33
981,512	37
982,45	33
983,389	36
984,325	33
985,263	35
986,2	32
987,138	38
988,074	30
989,01	35
989,946	38
990,881	36
991,817	36
992,752	38
993,688	35
994,623	40
995,557	32
996,492	32
997,425	35
998,36	36
999,293	32
1000,23	30
1001,16	36
1002,09	38
1003,02	34
1003,96	34
1004,89	36
1005,82	36
1006,75	36
1007,68	34
1008,61	33
1009,54	37
1010,47	32
1011,4	31
1012,33	32
1013,26	34
1014,19	33
1015,12	32
1016,05	36
1016,98	38
1017,9	34
1018,83	34
1019,76	36
1020,69	30
1021,61	28
1022,54	32
1023,47	35
1024,39	36
1025,32	36
1026,25	34
1027,17	38
1028,1	36
1029,02	37
1029,95	34
1030,87	32
1031,79	30
1032,72	36
1033,64	34
1034,56	31
1035,49	35
1036,41	34
1037,33	34
1038,25	30
1039,18	35
1040,1	36
1041,02	35
1041,94	34
1042,86	26
1043,78	34
1044,7	32
1045,62	33
1046,54	34
1047,46	37
1048,38	32
1049,3	36
1050,22	35
1051,14	33
1052,05	35
1052,97	34
1053,89	33
1054,81	32
1055,72	32
1056,64	30
1057,56	36
1058,47	37
1059,39	30
1060,31	36
1061,22	31
1062,14	34
1063,05	31
1063,97	36
1064,88	30
1065,8	34
1066,71	33
1067,62	34
1068,54	33
1069,45	31
1070,36	32
1071,28	37
1072,19	31
1073,1	33
1074,01	30
1074,92	36
1075,83	30
1076,75	36
1077,66	38
1078,57	28
1079,48	32
1080,39	33
1081,3	30
1082,21	36
1083,12	24
1084,02	32
1084,93	32
1085,84	33
1086,75	35
1087,66	32
1088,56	33
1089,47	32
1090,38	33
1091,29	28
1092,19	24
1093,1	35
1094	36
1094,91	33
1095,81	34
1096,72	33
1097,63	36
1098,53	34
1099,43	42
1100,34	36
1101,24	35
1102,15	30
1103,05	30
1103,95	30
1104,85	29
1105,76	35
1106,66	34
1107,56	34
1108,46	39
1109,36	32
1110,27	36
1111,17	34
1112,07	34
1112,97	35
1113,87	34
1114,77	34
1115,67	35
1116,57	36
1117,46	36
1118,36	40
1119,26	37
1120,16	33
1121,06	35
1121,96	34
1122,85	34
1123,75	34
1124,65	32
1125,55	37
1126,44	38
1127,34	35
1128,23	32
1129,13	36
1130,02	32
1130,92	31
1131,81	32
1132,71	34
1133,6	40
1134,5	42
1135,39	40
1136,28	35
1137,18	39
1138,07	32
1138,96	34
1139,85	36
1140,75	35
1141,64	34
1142,53	30
1143,42	36
1144,31	36
1145,2	38
1146,1	32
1146,98	32
1147,88	38
1148,76	30
1149,65	36
1150,54	36
1151,43	30
1152,32	33
1153,21	35
1154,1	34
1154,98	28
1155,87	28
1156,76	30
1157,65	34
1158,54	38
1159,42	36
1160,31	39
1161,19	33
1162,08	38
1162,97	38
1163,85	37
1164,73	32
1165,62	32
1166,5	32
1167,39	36
1168,27	34
1169,16	34
1170,04	39
1170,92	33
1171,81	37
1172,69	36
1173,57	39
1174,45	32
1175,33	37
1176,21	26
1177,1	40
1177,98	36
1178,86	36
1179,74	34
1180,62	34
1181,5	28
1182,38	35
1183,26	33
1184,14	35
1185,02	35
1185,89	36
1186,77	37
1187,65	34
1188,53	36
1189,41	33
1190,28	32
1191,16	36
1192,04	36
1192,91	30
1193,79	30
1194,67	32
1195,54	34
1196,42	34
1197,29	39
1198,17	32
1199,04	32
1199,92	40