File: RAMAN/MoS2_BM_UP/MoS2-2_2H (1).txt
#Acq. time (s)=	15
#Accumulations=	3
#Range (cm-¹)=	200...1200
#Windows=	1
#Auto scanning=	Off
#Autofocus=	Off
#AutoExposure=	Off
#Spike filter=	Multiple accum.
#Delay time (s)=	0
#Binning=	1
#Readout mode=	Signal
#DeNoise=	Off
#ICS correction=	Off
#Dark correction=	Off
#Inst. Process=	Off
#Detector Gain=	Best Dynamic Range
#Detector ADC=	45 kHz
#Detector temperature (°C)=	-60,1
#Instrument=	XploRA Plus
#Detector=	Syncerity OE
#Objective=	x50_VIS_LWD
#Grating=	2400 (400nm)
#Filter=	1%
#Laser=	532nm_Edge
#Slit (µm)=	50
#Hole (µm)=	100
#Temperature=	0
#Laser pol=	Circular
#Raman pol=	None
#StageXY=	75x50mm Scan+
#StageZ=	Z motor
#X (µm)=	0
#Y (µm)=	0
#Z (µm)=	404,9
#Full time(s)=	52
#Project=	A
#Sample=	B
#Site=	C
#Title=	D
#Remark=
#Date=	27.09.2024 14:00
#Acquired=	27.09.2024 14:00:30
#AxisType[0]=Intens
#AxisUnit[0]=Cnt
#AxisType[1]=Spectr
#AxisUnit[1]=1/cm
202,268	38
203,409	32
204,547	41
205,687	43
206,825	38
207,965	38
209,103	44
210,241	37
211,378	40
212,516	32
213,653	34
214,79	40
215,927	34
217,064	38
218,2	42
219,337	36
220,471	43
221,607	42
222,743	34
223,877	40
225,011	42
226,146	36
227,28	39
228,413	39
229,548	46
230,681	38
231,814	37
232,947	38
234,08	44
235,21	45
236,342	36
237,475	43
238,607	40
239,736	42
240,868	39
241,998	39
243,129	46
244,258	41
245,39	35
246,519	32
247,647	38
248,776	39
249,905	40
251,033	36
252,161	38
253,29	35
254,418	39
255,543	35
256,671	34
257,799	33
258,924	34
260,051	34
261,177	44
262,304	42
263,428	38
264,553	38
265,678	30
266,802	38
267,926	43
269,05	34
270,174	40
271,298	38
272,422	33
273,546	37
274,667	34
275,79	36
276,914	40
278,035	38
279,157	40
280,278	34
281,399	34
282,519	42
283,641	36
284,762	43
285,882	48
287,001	49
288,121	44
289,239	41
290,358	42
291,478	36
292,597	36
293,714	45
294,833	34
295,949	32
297,068	34
298,184	36
299,301	37
300,417	32
301,533	42
302,651	36
303,767	34
304,88	43
305,996	34
307,111	43
308,226	38
309,341	34
310,454	36
311,569	40
312,682	38
313,796	40
314,909	39
316,021	37
317,135	30
318,247	36
319,359	40
320,47	36
321,582	38
322,693	42
323,804	40
324,913	40
326,024	40
327,135	40
328,244	38
329,355	34
330,463	35
331,573	37
332,681	45
333,789	42
334,899	36
336,007	42
337,115	38
338,222	36
339,329	36
340,437	41
341,542	46
342,648	39
343,755	40
344,86	45
345,966	43
347,071	42
348,177	42
349,281	39
350,385	49
351,491	42
352,594	44
353,698	44
354,801	42
355,904	44
357,008	44
358,109	46
359,211	40
360,314	49
361,415	44
362,517	43
363,619	43
364,72	48
365,82	44
366,921	44
368,021	42
369,121	54
370,22	56
371,32	61
372,419	66
373,518	70
374,617	84
375,714	92
376,812	97
377,911	104
379,007	136
380,105	164
381,202	182
382,297	158
383,395	132
384,491	94
385,587	58
386,682	56
387,777	58
388,873	44
389,968	53
391,063	56
392,157	57
393,25	55
394,344	62
395,437	66
396,531	66
397,623	84
398,717	88
399,809	104
400,901	130
401,992	161
403,084	191
404,175	224
405,266	275
406,357	342
407,448	323
408,539	312
409,627	182
410,718	120
411,806	90
412,896	66
413,984	68
415,074	63
416,162	60
417,25	62
418,338	56
419,425	60
420,512	44
421,599	44
422,686	50
423,773	50
424,858	44
425,945	50
427,031	42
428,116	52
429,202	50
430,286	50
431,37	47
432,456	48
433,539	56
434,623	53
435,706	51
436,79	54
437,873	56
438,954	56
440,037	48
441,12	50
442,202	56
443,283	50
444,365	58
445,445	58
446,526	54
447,608	60
448,688	64
449,767	64
450,847	65
451,926	58
453,006	62
454,085	52
455,162	55
456,241	64
457,32	54
458,396	53
459,475	58
460,551	45
461,63	55
462,706	50
463,782	50
464,858	52
465,934	52
467,009	49
468,085	37
469,16	42
470,235	37
471,311	42
472,386	36
473,458	39
474,533	40
475,606	34
476,68	40
477,753	41
478,825	34
479,897	36
480,969	36
482,041	41
483,112	35
484,184	36
485,255	39
486,327	39
487,398	34
488,467	40
489,538	34
490,607	42
491,678	40
492,746	36
493,814	42
494,883	36
495,951	32
497,021	38
498,089	39
499,155	34
500,222	46
501,29	36
502,357	36
503,423	35
504,49	36
505,555	36
506,622	35
507,686	39
508,751	34
509,818	32
510,882	41
511,946	36
513,01	38
514,074	41
515,138	31
516,2	40
517,264	44
518,327	39
519,389	42
520,452	44
521,513	34
522,574	38
523,637	37
524,698	36
525,758	37
526,819	38
527,879	32
528,939	42
529,999	38
531,059	41
532,117	34
533,177	43
534,235	41
535,294	35
536,352	34
537,411	33
538,468	38
539,525	38
540,582	37
541,638	38
542,695	35
543,752	36
544,808	40
545,864	46
546,92	38
547,974	42
549,03	44
550,084	42
551,14	46
552,193	44
553,246	45
554,3	42
555,353	44
556,406	48
557,459	43
558,511	42
559,564	43
560,617	49
561,669	50
562,719	40
563,771	42
564,821	38
565,871	43
566,923	44
567,973	44
569,022	45
570,072	46
571,121	46
572,17	44
573,219	44
574,268	36
575,317	46
576,363	44
577,412	48
578,458	44
579,507	40
580,553	44
581,599	42
582,647	52
583,693	45
584,738	48
585,784	48
586,829	44
587,873	45
588,918	42
589,963	48
591,008	42
592,051	45
593,096	48
594,138	42
595,181	36
596,225	36
597,267	41
598,309	44
599,351	44
600,393	40
601,435	44
602,475	44
603,516	39
604,557	42
605,597	45
606,638	38
607,677	41
608,718	37
609,757	38
610,795	32
611,834	37
612,872	37
613,91	41
614,949	41
615,987	42
617,025	43
618,063	42
619,098	38
620,136	38
621,171	42
622,209	43
623,244	38
624,279	39
625,314	40
626,349	39
627,384	43
628,418	36
629,453	34
630,487	40
631,521	40
632,554	44
633,588	40
634,62	35
635,653	35
636,685	34
637,717	39
638,748	36
639,781	38
640,813	37
641,844	30
642,873	39
643,904	30
644,934	36
645,965	30
646,993	36
648,024	35
649,052	32
650,08	42
651,11	38
652,138	39
653,166	38
654,194	38
655,221	38
656,249	42
657,276	34
658,303	32
659,328	26
660,355	30
661,38	28
662,407	37
663,432	39
664,456	34
665,482	40
666,507	31
667,531	37
668,555	35
669,579	34
670,603	32
671,625	34
672,648	34
673,672	38
674,693	37
675,716	37
676,737	32
677,758	32
678,779	30
679,802	31
680,823	39
681,843	36
682,862	30
683,882	34
684,902	31
685,922	36
686,94	36
687,96	38
688,978	34
689,997	34
691,015	36
692,032	35
693,05	36
694,067	36
695,084	34
696,101	34
697,118	37
698,134	38
699,149	38
700,166	36
701,182	40
702,196	41
703,21	32
704,226	30
705,24	37
706,254	44
707,268	35
708,281	38
709,295	39
710,308	33
711,319	30
712,333	41
713,346	42
714,357	34
715,369	36
716,38	37
717,391	41
718,401	43
719,413	38
720,424	39
721,434	40
722,442	41
723,452	41
724,461	37
725,471	36
726,479	39
727,488	36
728,495	38
729,503	39
730,512	36
731,519	42
732,526	39
733,532	41
734,539	42
735,546	41
736,552	37
737,556	36
738,563	35
739,567	37
740,573	43
741,577	40
742,582	38
743,586	39
744,589	40
745,593	46
746,596	42
747,599	36
748,603	36
749,606	43
750,607	42
751,609	44
752,61	38
753,612	40
754,613	44
755,613	41
756,616	38
757,616	42
758,616	42
759,616	34
760,615	38
761,613	44
762,613	32
763,612	32
764,609	38
765,609	37
766,606	39
767,605	34
768,602	33
769,599	38
770,595	38
771,592	33
772,588	37
773,585	41
774,581	39
775,575	41
776,571	41
777,565	34
778,561	35
779,555	37
780,548	42
781,544	36
782,537	39
783,53	40
784,524	34
785,517	39
786,51	37
787,5	37
788,493	34
789,484	34
790,476	39
791,467	40
792,459	28
793,449	34
794,44	33
795,43	38
796,419	33
797,409	37
798,399	38
799,388	34
800,376	30
801,365	37
802,353	26
803,342	34
804,329	40
805,316	33
806,304	36
807,291	36
808,278	38
809,264	34
810,251	36
811,235	34
812,221	38
813,207	38
814,191	41
815,177	39
816,161	32
817,145	37
818,13	34
819,114	37
820,097	30
821,08	33
822,063	36
823,044	39
824,027	42
825,01	39
825,991	32
826,973	33
827,954	30
828,936	36
829,917	34
830,897	34
831,877	36
832,857	32
833,837	32
834,817	37
835,794	36
836,774	36
837,753	32
838,731	36
839,71	36
840,687	33
841,664	30
842,641	30
843,618	41
844,595	40
845,571	37
846,548	35
847,524	36
848,5	30
849,475	34
850,451	26
851,425	40
852,401	37
853,375	42
854,348	32
855,322	38
856,295	39
857,269	32
858,242	34
859,215	34
860,186	34
861,159	33
862,13	36
863,103	35
864,074	31
865,044	26
866,017	35
866,987	28
867,957	36
868,928	34
869,898	32
870,866	36
871,835	34
872,805	32
873,773	33
874,742	31
875,71	30
876,677	34
877,645	32
878,612	32
879,579	33
880,546	33
881,513	33
882,479	28
883,446	34
884,411	34
885,377	30
886,341	34
887,308	34
888,272	39
889,236	37
890,2	33
891,164	38
892,127	35
893,091	43
894,055	34
895,016	32
895,979	38
896,941	34
897,904	32
898,865	33
899,826	31
900,789	39
901,749	35
902,71	32
903,671	37
904,631	33
905,589	35
906,55	30
907,51	31
908,468	33
909,426	37
910,386	32
911,344	36
912,301	33
913,259	38
914,216	35
915,174	38
916,131	34
917,088	36
918,043	29
919	32
919,955	34
920,912	34
921,866	34
922,821	35
923,776	32
924,732	28
925,684	30
926,638	29
927,593	33
928,547	29
929,5	36
930,452	33
931,406	30
932,358	34
933,309	32
934,261	34
935,214	35
936,165	34
937,116	26
938,065	27
939,016	34
939,967	36
940,916	40
941,866	34
942,815	35
943,765	28
944,714	30
945,662	35
946,61	31
947,558	28
948,506	38
949,454	34
950,402	31
951,348	32
952,295	34
953,243	36
954,188	35
955,133	34
956,081	34
957,026	31
957,971	30
958,916	33
959,861	33
960,803	38
961,748	30
962,693	30
963,635	32
964,579	32
965,522	32
966,464	35
967,408	35
968,35	31
969,292	30
970,233	34
971,175	30
972,115	31
973,056	26
973,998	34
974,937	37
975,878	32
976,817	28
977,756	31
978,695	34
979,634	31
980,573	32
981,512	38
982,45	31
983,389	33
984,325	32
985,263	33
986,2	28
987,138	33
988,074	32
989,01	37
989,946	30
990,881	29
991,817	29
992,752	34
993,688	38
994,623	30
995,557	36
996,492	36
997,425	34
998,36	29
999,293	33
1000,23	26
1001,16	34
1002,09	32
1003,02	33
1003,96	33
1004,89	33
1005,82	26
1006,75	37
1007,68	34
1008,61	24
1009,54	31
1010,47	29
1011,4	31
1012,33	31
1013,26	33
1014,19	31
1015,12	28
1016,05	30
1016,98	33
1017,9	30
1018,83	28
1019,76	36
1020,69	30
1021,61	35
1022,54	32
1023,47	30
1024,39	35
1025,32	34
1026,25	29
1027,17	29
1028,1	26
1029,02	32
1029,95	28
1030,87	34
1031,79	33
1032,72	30
1033,64	30
1034,56	31
1035,49	30
1036,41	30
1037,33	34
1038,25	34
1039,18	31
1040,1	35
1041,02	36
1041,94	30
1042,86	35
1043,78	32
1044,7	32
1045,62	34
1046,54	33
1047,46	32
1048,38	32
1049,3	28
1050,22	28
1051,14	31
1052,05	32
1052,97	32
1053,89	32
1054,81	30
1055,72	31
1056,64	30
1057,56	30
1058,47	38
1059,39	31
1060,31	29
1061,22	33
1062,14	32
1063,05	36
1063,97	36
1064,88	34
1065,8	29
1066,71	34
1067,62	29
1068,54	28
1069,45	28
1070,36	28
1071,28	34
1072,19	32
1073,1	31
1074,01	30
1074,92	31
1075,83	32
1076,75	28
1077,66	31
1078,57	32
1079,48	30
1080,39	28
1081,3	30
1082,21	33
1083,12	36
1084,02	36
1084,93	30
1085,84	29
1086,75	29
1087,66	32
1088,56	31
1089,47	32
1090,38	22
1091,29	30
1092,19	37
1093,1	32
1094	30
1094,91	27
1095,81	35
1096,72	36
1097,63	35
1098,53	31
1099,43	30
1100,34	29
1101,24	30
1102,15	28
1103,05	26
1103,95	24
1104,85	33
1105,76	32
1106,66	34
1107,56	34
1108,46	34
1109,36	33
1110,27	36
1111,17	33
1112,07	33
1112,97	28
1113,87	24
1114,77	31
1115,67	36
1116,57	30
1117,46	30
1118,36	32
1119,26	32
1120,16	31
1121,06	32
1121,96	28
1122,85	26
1123,75	33
1124,65	36
1125,55	32
1126,44	34
1127,34	35
1128,23	34
1129,13	34
1130,02	30
1130,92	32
1131,81	34
1132,71	33
1133,6	33
1134,5	41
1135,39	34
1136,28	37
1137,18	32
1138,07	33
1138,96	20
1139,85	34
1140,75	26
1141,64	34
1142,53	33
1143,42	36
1144,31	38
1145,2	32
1146,1	33
1146,98	32
1147,88	33
1148,76	35
1149,65	28
1150,54	35
1151,43	36
1152,32	33
1153,21	35
1154,1	30
1154,98	31
1155,87	36
1156,76	33
1157,65	37
1158,54	28
1159,42	35
1160,31	37
1161,19	36
1162,08	33
1162,97	29
1163,85	29
1164,73	29
1165,62	34
1166,5	31
1167,39	34
1168,27	28
1169,16	34
1170,04	38
1170,92	33
1171,81	32
1172,69	32
1173,57	33
1174,45	33
1175,33	34
1176,21	26
1177,1	28
1177,98	32
1178,86	32
1179,74	35
1180,62	30
1181,5	30
1182,38	32
1183,26	36
1184,14	38
1185,02	37
1185,89	26
1186,77	30
1187,65	37
1188,53	35
1189,41	38
1190,28	33
1191,16	30
1192,04	32
1192,91	30
1193,79	34
1194,67	33
1195,54	39
1196,42	35
1197,29	32
1198,17	28
1199,04	28
1199,92	34