File: RAMAN/MoS2_BM_UP/MoS2-3H (1).txt
#Acq. time (s)=	15
#Accumulations=	3
#Range (cm-¹)=	200...1200
#Windows=	1
#Auto scanning=	Off
#Autofocus=	Off
#AutoExposure=	Off
#Spike filter=	Multiple accum.
#Delay time (s)=	0
#Binning=	1
#Readout mode=	Signal
#DeNoise=	Off
#ICS correction=	Off
#Dark correction=	Off
#Inst. Process=	Off
#Detector Gain=	Best Dynamic Range
#Detector ADC=	45 kHz
#Detector temperature (°C)=	-60,1
#Instrument=	XploRA Plus
#Detector=	Syncerity OE
#Objective=	x50_VIS_LWD
#Grating=	2400 (400nm)
#Filter=	1%
#Laser=	532nm_Edge
#Slit (µm)=	50
#Hole (µm)=	100
#Temperature=	0
#Laser pol=	Circular
#Raman pol=	None
#StageXY=	75x50mm Scan+
#StageZ=	Z motor
#X (µm)=	0
#Y (µm)=	0
#Z (µm)=	294,75
#Full time(s)=	52
#Project=	A
#Sample=	B
#Site=	C
#Title=	D
#Remark=
#Date=	27.09.2024 13:04
#Acquired=	27.09.2024 13:04:11
#AxisType[0]=Intens
#AxisUnit[0]=Cnt
#AxisType[1]=Spectr
#AxisUnit[1]=1/cm
202,268	30
203,409	27
204,547	32
205,687	30
206,825	35
207,965	33
209,103	28
210,241	36
211,378	30
212,516	30
213,653	33
214,79	31
215,927	38
217,064	33
218,2	38
219,337	30
220,471	30
221,607	32
222,743	34
223,877	33
225,011	34
226,146	30
227,28	32
228,413	32
229,548	36
230,681	35
231,814	32
232,947	31
234,08	27
235,21	36
236,342	28
237,475	30
238,607	34
239,736	28
240,868	31
241,998	28
243,129	41
244,258	32
245,39	31
246,519	32
247,647	32
248,776	30
249,905	36
251,033	32
252,161	35
253,29	32
254,418	34
255,543	32
256,671	34
257,799	34
258,924	30
260,051	31
261,177	36
262,304	32
263,428	26
264,553	34
265,678	31
266,802	35
267,926	28
269,05	37
270,174	32
271,298	32
272,422	38
273,546	33
274,667	26
275,79	31
276,914	36
278,035	33
279,157	34
280,278	30
281,399	24
282,519	29
283,641	35
284,762	38
285,882	42
287,001	45
288,121	34
289,239	32
290,358	31
291,478	35
292,597	32
293,714	36
294,833	39
295,949	29
297,068	30
298,184	36
299,301	36
300,417	33
301,533	33
302,651	31
303,767	32
304,88	32
305,996	28
307,111	36
308,226	33
309,341	34
310,454	36
311,569	30
312,682	35
313,796	32
314,909	35
316,021	33
317,135	32
318,247	30
319,359	35
320,47	34
321,582	36
322,693	37
323,804	32
324,913	32
326,024	36
327,135	27
328,244	37
329,355	32
330,463	32
331,573	32
332,681	34
333,789	39
334,899	30
336,007	33
337,115	28
338,222	36
339,329	32
340,437	33
341,542	35
342,648	34
343,755	31
344,86	31
345,966	38
347,071	40
348,177	34
349,281	32
350,385	34
351,491	36
352,594	29
353,698	32
354,801	35
355,904	39
357,008	34
358,109	37
359,211	36
360,314	32
361,415	32
362,517	34
363,619	35
364,72	32
365,82	40
366,921	32
368,021	35
369,121	35
370,22	40
371,32	40
372,419	41
373,518	46
374,617	41
375,714	49
376,812	56
377,911	64
379,007	77
380,105	105
381,202	130
382,297	136
383,395	121
384,491	93
385,587	64
386,682	44
387,777	38
388,873	34
389,968	37
391,063	39
392,157	30
393,25	36
394,344	41
395,437	35
396,531	41
397,623	38
398,717	40
399,809	53
400,901	48
401,992	68
403,084	87
404,175	108
405,266	152
406,357	232
407,448	276
408,539	256
409,627	183
410,718	110
411,806	78
412,896	57
413,984	48
415,074	50
416,162	40
417,25	42
418,338	39
419,425	48
420,512	37
421,599	36
422,686	35
423,773	38
424,858	38
425,945	45
427,031	41
428,116	37
429,202	42
430,286	36
431,37	40
432,456	40
433,539	40
434,623	42
435,706	36
436,79	42
437,873	37
438,954	42
440,037	41
441,12	41
442,202	42
443,283	38
444,365	40
445,445	40
446,526	43
447,608	47
448,688	44
449,767	41
450,847	52
451,926	48
453,006	38
454,085	42
455,162	46
456,241	47
457,32	38
458,396	43
459,475	42
460,551	38
461,63	42
462,706	46
463,782	45
464,858	38
465,934	43
467,009	41
468,085	41
469,16	38
470,235	33
471,311	34
472,386	34
473,458	28
474,533	28
475,606	35
476,68	33
477,753	28
478,825	30
479,897	36
480,969	33
482,041	29
483,112	29
484,184	32
485,255	33
486,327	29
487,398	32
488,467	34
489,538	28
490,607	30
491,678	37
492,746	30
493,814	34
494,883	29
495,951	33
497,021	35
498,089	34
499,155	33
500,222	35
501,29	24
502,357	28
503,423	33
504,49	32
505,555	33
506,622	30
507,686	35
508,751	36
509,818	38
510,882	32
511,946	33
513,01	34
514,074	28
515,138	33
516,2	32
517,264	35
518,327	32
519,389	34
520,452	36
521,513	34
522,574	28
523,637	29
524,698	34
525,758	36
526,819	30
527,879	31
528,939	32
529,999	31
531,059	34
532,117	29
533,177	28
534,235	34
535,294	33
536,352	36
537,411	34
538,468	37
539,525	32
540,582	29
541,638	32
542,695	35
543,752	24
544,808	33
545,864	34
546,92	36
547,974	35
549,03	35
550,084	31
551,14	38
552,193	39
553,246	32
554,3	36
555,353	35
556,406	32
557,459	38
558,511	39
559,564	37
560,617	29
561,669	39
562,719	36
563,771	36
564,821	35
565,871	38
566,923	38
567,973	36
569,022	38
570,072	31
571,121	40
572,17	39
573,219	36
574,268	38
575,317	40
576,363	34
577,412	35
578,458	38
579,507	34
580,553	33
581,599	32
582,647	38
583,693	39
584,738	39
585,784	37
586,829	31
587,873	36
588,918	43
589,963	35
591,008	33
592,051	40
593,096	40
594,138	41
595,181	38
596,225	36
597,267	39
598,309	38
599,351	34
600,393	35
601,435	34
602,475	35
603,516	36
604,557	33
605,597	35
606,638	31
607,677	37
608,718	32
609,757	39
610,795	32
611,834	36
612,872	33
613,91	24
614,949	34
615,987	34
617,025	36
618,063	39
619,098	36
620,136	37
621,171	32
622,209	32
623,244	35
624,279	37
625,314	36
626,349	32
627,384	32
628,418	26
629,453	38
630,487	32
631,521	35
632,554	29
633,588	35
634,62	28
635,653	24
636,685	36
637,717	38
638,748	32
639,781	34
640,813	35
641,844	33
642,873	31
643,904	30
644,934	34
645,965	39
646,993	29
648,024	30
649,052	26
650,08	34
651,11	35
652,138	32
653,166	38
654,194	35
655,221	32
656,249	30
657,276	31
658,303	30
659,328	34
660,355	29
661,38	34
662,407	37
663,432	33
664,456	40
665,482	31
666,507	33
667,531	33
668,555	36
669,579	30
670,603	28
671,625	28
672,648	30
673,672	35
674,693	36
675,716	30
676,737	32
677,758	35
678,779	32
679,802	29
680,823	30
681,843	32
682,862	34
683,882	26
684,902	34
685,922	36
686,94	28
687,96	26
688,978	28
689,997	32
691,015	36
692,032	26
693,05	24
694,067	32
695,084	26
696,101	32
697,118	28
698,134	34
699,149	31
700,166	34
701,182	28
702,196	24
703,21	32
704,226	28
705,24	38
706,254	30
707,268	33
708,281	33
709,295	34
710,308	32
711,319	34
712,333	32
713,346	35
714,357	39
715,369	32
716,38	26
717,391	34
718,401	36
719,413	32
720,424	36
721,434	32
722,442	34
723,452	31
724,461	26
725,471	32
726,479	34
727,488	35
728,495	38
729,503	36
730,512	32
731,519	37
732,526	28
733,532	33
734,539	36
735,546	31
736,552	30
737,556	30
738,563	36
739,567	31
740,573	35
741,577	34
742,582	34
743,586	28
744,589	30
745,593	34
746,596	36
747,599	34
748,603	37
749,606	39
750,607	38
751,609	32
752,61	36
753,612	36
754,613	36
755,613	39
756,616	41
757,616	36
758,616	34
759,616	32
760,615	33
761,613	24
762,613	38
763,612	34
764,609	37
765,609	38
766,606	34
767,605	29
768,602	37
769,599	29
770,595	32
771,592	35
772,588	38
773,585	36
774,581	40
775,575	34
776,571	33
777,565	30
778,561	36
779,555	31
780,548	34
781,544	36
782,537	34
783,53	34
784,524	34
785,517	36
786,51	34
787,5	35
788,493	28
789,484	33
790,476	34
791,467	32
792,459	29
793,449	28
794,44	32
795,43	29
796,419	34
797,409	32
798,399	34
799,388	33
800,376	34
801,365	30
802,353	32
803,342	28
804,329	37
805,316	32
806,304	26
807,291	35
808,278	30
809,264	31
810,251	33
811,235	34
812,221	28
813,207	28
814,191	34
815,177	28
816,161	37
817,145	28
818,13	34
819,114	34
820,097	37
821,08	31
822,063	37
823,044	34
824,027	35
825,01	33
825,991	38
826,973	36
827,954	30
828,936	24
829,917	26
830,897	36
831,877	32
832,857	31
833,837	34
834,817	29
835,794	32
836,774	24
837,753	35
838,731	32
839,71	33
840,687	30
841,664	31
842,641	34
843,618	38
844,595	36
845,571	34
846,548	35
847,524	28
848,5	34
849,475	30
850,451	31
851,425	32
852,401	35
853,375	40
854,348	31
855,322	30
856,295	28
857,269	33
858,242	24
859,215	35
860,186	30
861,159	28
862,13	32
863,103	33
864,074	31
865,044	29
866,017	33
866,987	25
867,957	33
868,928	34
869,898	30
870,866	35
871,835	30
872,805	27
873,773	32
874,742	34
875,71	35
876,677	32
877,645	26
878,612	28
879,579	31
880,546	33
881,513	33
882,479	34
883,446	33
884,411	32
885,377	30
886,341	27
887,308	35
888,272	32
889,236	28
890,2	28
891,164	26
892,127	33
893,091	29
894,055	30
895,016	32
895,979	30
896,941	30
897,904	30
898,865	33
899,826	32
900,789	36
901,749	26
902,71	28
903,671	31
904,631	28
905,589	28
906,55	28
907,51	27
908,468	39
909,426	38
910,386	26
911,344	38
912,301	34
913,259	29
914,216	33
915,174	30
916,131	24
917,088	28
918,043	26
919	34
919,955	28
920,912	30
921,866	32
922,821	33
923,776	28
924,732	32
925,684	28
926,638	30
927,593	31
928,547	32
929,5	31
930,452	33
931,406	28
932,358	30
933,309	27
934,261	29
935,214	30
936,165	36
937,116	34
938,065	30
939,016	32
939,967	33
940,916	30
941,866	26
942,815	31
943,765	26
944,714	34
945,662	32
946,61	34
947,558	32
948,506	24
949,454	36
950,402	34
951,348	32
952,295	35
953,243	26
954,188	34
955,133	31
956,081	30
957,026	30
957,971	34
958,916	33
959,861	35
960,803	35
961,748	34
962,693	32
963,635	29
964,579	32
965,522	31
966,464	31
967,408	33
968,35	35
969,292	28
970,233	33
971,175	26
972,115	30
973,056	34
973,998	28
974,937	32
975,878	26
976,817	34
977,756	30
978,695	28
979,634	28
980,573	30
981,512	36
982,45	28
983,389	30
984,325	26
985,263	29
986,2	34
987,138	36
988,074	31
989,01	28
989,946	30
990,881	28
991,817	34
992,752	31
993,688	32
994,623	24
995,557	31
996,492	29
997,425	32
998,36	26
999,293	30
1000,23	30
1001,16	32
1002,09	29
1003,02	32
1003,96	32
1004,89	33
1005,82	31
1006,75	30
1007,68	28
1008,61	30
1009,54	26
1010,47	32
1011,4	32
1012,33	32
1013,26	34
1014,19	35
1015,12	28
1016,05	26
1016,98	28
1017,9	30
1018,83	34
1019,76	28
1020,69	34
1021,61	37
1022,54	34
1023,47	27
1024,39	33
1025,32	32
1026,25	24
1027,17	27
1028,1	31
1029,02	31
1029,95	26
1030,87	27
1031,79	33
1032,72	31
1033,64	26
1034,56	28
1035,49	28
1036,41	26
1037,33	26
1038,25	28
1039,18	28
1040,1	29
1041,02	34
1041,94	27
1042,86	29
1043,78	30
1044,7	34
1045,62	29
1046,54	30
1047,46	36
1048,38	31
1049,3	36
1050,22	33
1051,14	34
1052,05	28
1052,97	35
1053,89	32
1054,81	30
1055,72	29
1056,64	33
1057,56	20
1058,47	38
1059,39	30
1060,31	34
1061,22	26
1062,14	29
1063,05	36
1063,97	30
1064,88	31
1065,8	33
1066,71	30
1067,62	30
1068,54	28
1069,45	30
1070,36	24
1071,28	28
1072,19	30
1073,1	32
1074,01	32
1074,92	32
1075,83	24
1076,75	29
1077,66	30
1078,57	33
1079,48	18
1080,39	25
1081,3	30
1082,21	34
1083,12	32
1084,02	30
1084,93	26
1085,84	29
1086,75	29
1087,66	35
1088,56	30
1089,47	32
1090,38	28
1091,29	30
1092,19	29
1093,1	32
1094	32
1094,91	28
1095,81	35
1096,72	34
1097,63	33
1098,53	28
1099,43	27
1100,34	22
1101,24	30
1102,15	32
1103,05	31
1103,95	28
1104,85	32
1105,76	28
1106,66	32
1107,56	29
1108,46	26
1109,36	27
1110,27	34
1111,17	32
1112,07	32
1112,97	26
1113,87	33
1114,77	34
1115,67	34
1116,57	28
1117,46	24
1118,36	36
1119,26	26
1120,16	33
1121,06	30
1121,96	30
1122,85	27
1123,75	27
1124,65	32
1125,55	32
1126,44	30
1127,34	33
1128,23	32
1129,13	25
1130,02	34
1130,92	26
1131,81	36
1132,71	30
1133,6	32
1134,5	40
1135,39	28
1136,28	29
1137,18	32
1138,07	27
1138,96	28
1139,85	27
1140,75	22
1141,64	32
1142,53	30
1143,42	31
1144,31	33
1145,2	30
1146,1	31
1146,98	31
1147,88	35
1148,76	27
1149,65	30
1150,54	28
1151,43	33
1152,32	28
1153,21	30
1154,1	29
1154,98	32
1155,87	31
1156,76	33
1157,65	29
1158,54	31
1159,42	26
1160,31	24
1161,19	29
1162,08	34
1162,97	30
1163,85	33
1164,73	30
1165,62	33
1166,5	30
1167,39	32
1168,27	32
1169,16	28
1170,04	31
1170,92	30
1171,81	34
1172,69	34
1173,57	22
1174,45	33
1175,33	32
1176,21	32
1177,1	28
1177,98	29
1178,86	32
1179,74	26
1180,62	36
1181,5	22
1182,38	30
1183,26	27
1184,14	36
1185,02	30
1185,89	32
1186,77	28
1187,65	27
1188,53	28
1189,41	29
1190,28	30
1191,16	27
1192,04	31
1192,91	32
1193,79	31
1194,67	33
1195,54	32
1196,42	25
1197,29	34
1198,17	34
1199,04	32
1199,92	32