File: RAMAN/MoS2_BM_UP/MoS2-2_4H (1).txt
#Acq. time (s)=	15
#Accumulations=	3
#Range (cm-¹)=	200...1200
#Windows=	1
#Auto scanning=	Off
#Autofocus=	Off
#AutoExposure=	Off
#Spike filter=	Multiple accum.
#Delay time (s)=	0
#Binning=	1
#Readout mode=	Signal
#DeNoise=	Off
#ICS correction=	Off
#Dark correction=	Off
#Inst. Process=	Off
#Detector Gain=	Best Dynamic Range
#Detector ADC=	45 kHz
#Detector temperature (°C)=	-60,1
#Instrument=	XploRA Plus
#Detector=	Syncerity OE
#Objective=	x50_VIS_LWD
#Grating=	2400 (400nm)
#Filter=	1%
#Laser=	532nm_Edge
#Slit (µm)=	50
#Hole (µm)=	100
#Temperature=	0
#Laser pol=	Circular
#Raman pol=	None
#StageXY=	75x50mm Scan+
#StageZ=	Z motor
#X (µm)=	0
#Y (µm)=	0
#Z (µm)=	371,55
#Full time(s)=	52
#Project=	A
#Sample=	B
#Site=	C
#Title=	D
#Remark=
#Date=	27.09.2024 14:09
#Acquired=	27.09.2024 14:09:40
#AxisType[0]=Intens
#AxisUnit[0]=Cnt
#AxisType[1]=Spectr
#AxisUnit[1]=1/cm
202,268	45
203,409	44
204,547	47
205,687	46
206,825	48
207,965	44
209,103	51
210,241	44
211,378	48
212,516	44
213,653	46
214,79	40
215,927	43
217,064	36
218,2	46
219,337	44
220,471	42
221,607	40
222,743	38
223,877	44
225,011	45
226,146	43
227,28	40
228,413	47
229,548	42
230,681	43
231,814	45
232,947	38
234,08	41
235,21	36
236,342	42
237,475	41
238,607	41
239,736	36
240,868	46
241,998	42
243,129	43
244,258	38
245,39	38
246,519	44
247,647	33
248,776	41
249,905	41
251,033	42
252,161	42
253,29	42
254,418	45
255,543	38
256,671	38
257,799	43
258,924	37
260,051	40
261,177	46
262,304	47
263,428	42
264,553	40
265,678	37
266,802	41
267,926	41
269,05	39
270,174	42
271,298	37
272,422	34
273,546	42
274,667	41
275,79	42
276,914	39
278,035	41
279,157	38
280,278	37
281,399	40
282,519	48
283,641	53
284,762	50
285,882	52
287,001	54
288,121	46
289,239	42
290,358	41
291,478	40
292,597	36
293,714	45
294,833	39
295,949	38
297,068	40
298,184	41
299,301	44
300,417	41
301,533	42
302,651	36
303,767	38
304,88	38
305,996	46
307,111	43
308,226	40
309,341	44
310,454	40
311,569	44
312,682	44
313,796	44
314,909	41
316,021	47
317,135	36
318,247	49
319,359	44
320,47	49
321,582	46
322,693	52
323,804	49
324,913	40
326,024	46
327,135	42
328,244	42
329,355	42
330,463	38
331,573	46
332,681	42
333,789	47
334,899	44
336,007	46
337,115	41
338,222	44
339,329	44
340,437	41
341,542	46
342,648	44
343,755	45
344,86	47
345,966	42
347,071	45
348,177	44
349,281	44
350,385	47
351,491	52
352,594	44
353,698	51
354,801	43
355,904	51
357,008	46
358,109	52
359,211	50
360,314	52
361,415	46
362,517	54
363,619	46
364,72	54
365,82	56
366,921	56
368,021	56
369,121	60
370,22	66
371,32	68
372,419	66
373,518	74
374,617	91
375,714	109
376,812	129
377,911	162
379,007	220
380,105	284
381,202	331
382,297	292
383,395	210
384,491	135
385,587	94
386,682	72
387,777	67
388,873	63
389,968	55
391,063	60
392,157	60
393,25	65
394,344	68
395,437	73
396,531	71
397,623	83
398,717	97
399,809	116
400,901	140
401,992	188
403,084	264
404,175	357
405,266	534
406,357	649
407,448	633
408,539	464
409,627	281
410,718	183
411,806	131
412,896	100
413,984	82
415,074	82
416,162	68
417,25	63
418,338	66
419,425	65
420,512	62
421,599	68
422,686	62
423,773	66
424,858	62
425,945	62
427,031	65
428,116	66
429,202	68
430,286	60
431,37	60
432,456	55
433,539	65
434,623	64
435,706	61
436,79	63
437,873	63
438,954	60
440,037	68
441,12	72
442,202	66
443,283	67
444,365	66
445,445	72
446,526	75
447,608	76
448,688	80
449,767	79
450,847	73
451,926	76
453,006	71
454,085	74
455,162	79
456,241	76
457,32	70
458,396	70
459,475	67
460,551	63
461,63	66
462,706	64
463,782	68
464,858	62
465,934	62
467,009	61
468,085	50
469,16	50
470,235	47
471,311	44
472,386	43
473,458	40
474,533	44
475,606	40
476,68	45
477,753	40
478,825	46
479,897	34
480,969	35
482,041	40
483,112	38
484,184	42
485,255	38
486,327	38
487,398	37
488,467	38
489,538	32
490,607	39
491,678	48
492,746	45
493,814	42
494,883	38
495,951	43
497,021	38
498,089	46
499,155	38
500,222	40
501,29	36
502,357	39
503,423	37
504,49	48
505,555	43
506,622	41
507,686	39
508,751	42
509,818	43
510,882	40
511,946	39
513,01	38
514,074	44
515,138	38
516,2	38
517,264	41
518,327	38
519,389	42
520,452	36
521,513	44
522,574	38
523,637	42
524,698	46
525,758	44
526,819	37
527,879	42
528,939	40
529,999	32
531,059	42
532,117	46
533,177	44
534,235	42
535,294	42
536,352	37
537,411	41
538,468	38
539,525	46
540,582	34
541,638	47
542,695	46
543,752	48
544,808	49
545,864	40
546,92	42
547,974	44
549,03	47
550,084	44
551,14	46
552,193	44
553,246	40
554,3	45
555,353	46
556,406	50
557,459	50
558,511	52
559,564	53
560,617	48
561,669	52
562,719	46
563,771	48
564,821	53
565,871	52
566,923	61
567,973	51
569,022	52
570,072	53
571,121	54
572,17	48
573,219	49
574,268	48
575,317	52
576,363	51
577,412	44
578,458	60
579,507	46
580,553	51
581,599	46
582,647	54
583,693	46
584,738	49
585,784	50
586,829	50
587,873	58
588,918	58
589,963	55
591,008	53
592,051	54
593,096	54
594,138	55
595,181	56
596,225	52
597,267	49
598,309	58
599,351	46
600,393	52
601,435	46
602,475	48
603,516	48
604,557	44
605,597	46
606,638	44
607,677	42
608,718	46
609,757	45
610,795	47
611,834	43
612,872	46
613,91	41
614,949	44
615,987	43
617,025	36
618,063	41
619,098	42
620,136	42
621,171	43
622,209	44
623,244	45
624,279	43
625,314	47
626,349	44
627,384	41
628,418	40
629,453	34
630,487	47
631,521	44
632,554	43
633,588	42
634,62	37
635,653	40
636,685	38
637,717	38
638,748	38
639,781	43
640,813	43
641,844	38
642,873	39
643,904	37
644,934	40
645,965	35
646,993	40
648,024	39
649,052	40
650,08	36
651,11	34
652,138	38
653,166	42
654,194	38
655,221	37
656,249	38
657,276	32
658,303	38
659,328	36
660,355	30
661,38	37
662,407	37
663,432	40
664,456	37
665,482	43
666,507	34
667,531	33
668,555	32
669,579	34
670,603	37
671,625	38
672,648	41
673,672	36
674,693	37
675,716	34
676,737	34
677,758	39
678,779	41
679,802	36
680,823	33
681,843	37
682,862	35
683,882	34
684,902	35
685,922	35
686,94	42
687,96	38
688,978	38
689,997	42
691,015	39
692,032	42
693,05	38
694,067	38
695,084	36
696,101	34
697,118	40
698,134	42
699,149	39
700,166	35
701,182	43
702,196	39
703,21	44
704,226	36
705,24	30
706,254	40
707,268	38
708,281	42
709,295	36
710,308	41
711,319	35
712,333	32
713,346	43
714,357	44
715,369	37
716,38	38
717,391	34
718,401	40
719,413	41
720,424	44
721,434	43
722,442	46
723,452	36
724,461	41
725,471	40
726,479	44
727,488	42
728,495	40
729,503	42
730,512	38
731,519	45
732,526	46
733,532	40
734,539	47
735,546	42
736,552	45
737,556	45
738,563	44
739,567	42
740,573	40
741,577	50
742,582	44
743,586	47
744,589	46
745,593	45
746,596	48
747,599	38
748,603	50
749,606	43
750,607	42
751,609	54
752,61	49
753,612	47
754,613	47
755,613	44
756,616	48
757,616	46
758,616	45
759,616	44
760,615	44
761,613	41
762,613	43
763,612	42
764,609	42
765,609	40
766,606	43
767,605	40
768,602	34
769,599	38
770,595	38
771,592	40
772,588	38
773,585	47
774,581	38
775,575	42
776,571	43
777,565	39
778,561	41
779,555	41
780,548	50
781,544	44
782,537	39
783,53	41
784,524	42
785,517	42
786,51	42
787,5	45
788,493	36
789,484	38
790,476	38
791,467	36
792,459	39
793,449	38
794,44	36
795,43	34
796,419	37
797,409	34
798,399	36
799,388	40
800,376	38
801,365	32
802,353	34
803,342	38
804,329	34
805,316	38
806,304	42
807,291	37
808,278	38
809,264	39
810,251	37
811,235	38
812,221	42
813,207	38
814,191	34
815,177	37
816,161	38
817,145	41
818,13	44
819,114	42
820,097	40
821,08	40
822,063	38
823,044	40
824,027	40
825,01	38
825,991	39
826,973	39
827,954	40
828,936	30
829,917	33
830,897	35
831,877	36
832,857	41
833,837	38
834,817	36
835,794	35
836,774	38
837,753	38
838,731	36
839,71	38
840,687	30
841,664	44
842,641	40
843,618	40
844,595	38
845,571	42
846,548	36
847,524	37
848,5	33
849,475	32
850,451	37
851,425	40
852,401	40
853,375	36
854,348	32
855,322	41
856,295	38
857,269	37
858,242	28
859,215	34
860,186	38
861,159	33
862,13	33
863,103	34
864,074	32
865,044	37
866,017	34
866,987	30
867,957	32
868,928	30
869,898	35
870,866	36
871,835	38
872,805	30
873,773	36
874,742	33
875,71	39
876,677	39
877,645	30
878,612	36
879,579	34
880,546	34
881,513	34
882,479	38
883,446	41
884,411	38
885,377	34
886,341	34
887,308	36
888,272	35
889,236	30
890,2	35
891,164	34
892,127	36
893,091	38
894,055	34
895,016	37
895,979	39
896,941	34
897,904	28
898,865	35
899,826	38
900,789	34
901,749	33
902,71	28
903,671	36
904,631	35
905,589	39
906,55	32
907,51	31
908,468	39
909,426	35
910,386	35
911,344	32
912,301	38
913,259	37
914,216	32
915,174	36
916,131	35
917,088	36
918,043	30
919	32
919,955	29
920,912	32
921,866	36
922,821	32
923,776	34
924,732	29
925,684	37
926,638	36
927,593	32
928,547	32
929,5	35
930,452	35
931,406	36
932,358	34
933,309	30
934,261	35
935,214	34
936,165	36
937,116	37
938,065	36
939,016	33
939,967	37
940,916	39
941,866	34
942,815	32
943,765	35
944,714	30
945,662	34
946,61	28
947,558	32
948,506	39
949,454	29
950,402	37
951,348	33
952,295	34
953,243	32
954,188	38
955,133	36
956,081	32
957,026	33
957,971	32
958,916	32
959,861	34
960,803	39
961,748	38
962,693	41
963,635	37
964,579	37
965,522	34
966,464	35
967,408	38
968,35	33
969,292	32
970,233	30
971,175	32
972,115	31
973,056	30
973,998	33
974,937	33
975,878	32
976,817	33
977,756	30
978,695	32
979,634	34
980,573	36
981,512	34
982,45	34
983,389	41
984,325	30
985,263	35
986,2	30
987,138	36
988,074	32
989,01	34
989,946	32
990,881	36
991,817	38
992,752	34
993,688	32
994,623	34
995,557	31
996,492	38
997,425	32
998,36	28
999,293	37
1000,23	34
1001,16	33
1002,09	35
1003,02	35
1003,96	37
1004,89	38
1005,82	34
1006,75	37
1007,68	34
1008,61	34
1009,54	32
1010,47	29
1011,4	26
1012,33	29
1013,26	36
1014,19	36
1015,12	32
1016,05	33
1016,98	32
1017,9	30
1018,83	44
1019,76	31
1020,69	34
1021,61	32
1022,54	34
1023,47	34
1024,39	34
1025,32	30
1026,25	32
1027,17	28
1028,1	34
1029,02	36
1029,95	32
1030,87	30
1031,79	36
1032,72	38
1033,64	34
1034,56	32
1035,49	32
1036,41	32
1037,33	34
1038,25	34
1039,18	34
1040,1	34
1041,02	28
1041,94	34
1042,86	32
1043,78	30
1044,7	37
1045,62	32
1046,54	30
1047,46	28
1048,38	34
1049,3	28
1050,22	31
1051,14	35
1052,05	32
1052,97	26
1053,89	30
1054,81	32
1055,72	30
1056,64	30
1057,56	35
1058,47	36
1059,39	36
1060,31	32
1061,22	31
1062,14	31
1063,05	36
1063,97	32
1064,88	28
1065,8	33
1066,71	39
1067,62	32
1068,54	32
1069,45	34
1070,36	29
1071,28	31
1072,19	34
1073,1	28
1074,01	32
1074,92	29
1075,83	33
1076,75	30
1077,66	34
1078,57	34
1079,48	26
1080,39	34
1081,3	28
1082,21	32
1083,12	37
1084,02	30
1084,93	34
1085,84	36
1086,75	30
1087,66	30
1088,56	32
1089,47	33
1090,38	36
1091,29	34
1092,19	32
1093,1	28
1094	27
1094,91	29
1095,81	30
1096,72	33
1097,63	33
1098,53	36
1099,43	30
1100,34	32
1101,24	32
1102,15	25
1103,05	31
1103,95	30
1104,85	32
1105,76	33
1106,66	28
1107,56	39
1108,46	34
1109,36	30
1110,27	28
1111,17	34
1112,07	32
1112,97	35
1113,87	28
1114,77	34
1115,67	38
1116,57	29
1117,46	30
1118,36	33
1119,26	30
1120,16	32
1121,06	31
1121,96	29
1122,85	35
1123,75	31
1124,65	32
1125,55	34
1126,44	32
1127,34	28
1128,23	30
1129,13	38
1130,02	31
1130,92	32
1131,81	34
1132,71	30
1133,6	34
1134,5	34
1135,39	32
1136,28	31
1137,18	31
1138,07	33
1138,96	26
1139,85	28
1140,75	32
1141,64	34
1142,53	24
1143,42	31
1144,31	33
1145,2	32
1146,1	33
1146,98	34
1147,88	40
1148,76	28
1149,65	34
1150,54	32
1151,43	32
1152,32	33
1153,21	29
1154,1	32
1154,98	30
1155,87	30
1156,76	26
1157,65	42
1158,54	38
1159,42	31
1160,31	31
1161,19	32
1162,08	34
1162,97	35
1163,85	28
1164,73	30
1165,62	33
1166,5	31
1167,39	30
1168,27	39
1169,16	32
1170,04	31
1170,92	38
1171,81	31
1172,69	37
1173,57	34
1174,45	32
1175,33	35
1176,21	33
1177,1	35
1177,98	30
1178,86	30
1179,74	33
1180,62	32
1181,5	31
1182,38	35
1183,26	29
1184,14	31
1185,02	35
1185,89	35
1186,77	32
1187,65	32
1188,53	37
1189,41	35
1190,28	30
1191,16	31
1192,04	29
1192,91	32
1193,79	31
1194,67	35
1195,54	32
1196,42	32
1197,29	33
1198,17	39
1199,04	34
1199,92	39