File: RAMAN/MoS2_BM_UP/MoS2-10H (1).txt
#Acq. time (s)=	15
#Accumulations=	3
#Range (cm-¹)=	200...1200
#Windows=	1
#Auto scanning=	Off
#Autofocus=	Off
#AutoExposure=	Off
#Spike filter=	Multiple accum.
#Delay time (s)=	0
#Binning=	1
#Readout mode=	Signal
#DeNoise=	Off
#ICS correction=	Off
#Dark correction=	Off
#Inst. Process=	Off
#Detector Gain=	Best Dynamic Range
#Detector ADC=	45 kHz
#Detector temperature (°C)=	-60,1
#Instrument=	XploRA Plus
#Detector=	Syncerity OE
#Objective=	x50_VIS_LWD
#Grating=	2400 (400nm)
#Filter=	1%
#Laser=	532nm_Edge
#Slit (µm)=	50
#Hole (µm)=	100
#Temperature=	0
#Laser pol=	Circular
#Raman pol=	None
#StageXY=	75x50mm Scan+
#StageZ=	Z motor
#X (µm)=	0
#Y (µm)=	0
#Z (µm)=	410,3
#Full time(s)=	52
#Project=	A
#Sample=	B
#Site=	C
#Title=	D
#Remark=
#Date=	27.09.2024 13:19
#Acquired=	27.09.2024 13:19:34
#AxisType[0]=Intens
#AxisUnit[0]=Cnt
#AxisType[1]=Spectr
#AxisUnit[1]=1/cm
202,268	67
203,409	63
204,547	62
205,687	70
206,825	63
207,965	62
209,103	68
210,241	64
211,378	69
212,516	70
213,653	66
214,79	60
215,927	58
217,064	72
218,2	69
219,337	67
220,471	66
221,607	68
222,743	66
223,877	73
225,011	73
226,146	65
227,28	64
228,413	66
229,548	69
230,681	65
231,814	52
232,947	67
234,08	59
235,21	70
236,342	58
237,475	58
238,607	61
239,736	59
240,868	64
241,998	59
243,129	66
244,258	62
245,39	60
246,519	60
247,647	58
248,776	57
249,905	58
251,033	54
252,161	62
253,29	58
254,418	60
255,543	62
256,671	53
257,799	54
258,924	60
260,051	56
261,177	58
262,304	55
263,428	66
264,553	60
265,678	56
266,802	52
267,926	60
269,05	58
270,174	60
271,298	59
272,422	56
273,546	57
274,667	57
275,79	54
276,914	48
278,035	57
279,157	65
280,278	54
281,399	57
282,519	67
283,641	79
284,762	81
285,882	82
287,001	70
288,121	72
289,239	60
290,358	58
291,478	58
292,597	52
293,714	68
294,833	59
295,949	61
297,068	61
298,184	52
299,301	64
300,417	60
301,533	67
302,651	59
303,767	61
304,88	62
305,996	54
307,111	59
308,226	55
309,341	54
310,454	58
311,569	62
312,682	65
313,796	65
314,909	61
316,021	59
317,135	56
318,247	63
319,359	65
320,47	58
321,582	66
322,693	71
323,804	64
324,913	56
326,024	67
327,135	65
328,244	71
329,355	62
330,463	61
331,573	61
332,681	66
333,789	60
334,899	56
336,007	60
337,115	67
338,222	66
339,329	64
340,437	59
341,542	66
342,648	70
343,755	68
344,86	58
345,966	75
347,071	62
348,177	63
349,281	71
350,385	69
351,491	65
352,594	73
353,698	64
354,801	68
355,904	75
357,008	70
358,109	75
359,211	78
360,314	70
361,415	68
362,517	77
363,619	79
364,72	75
365,82	82
366,921	82
368,021	62
369,121	83
370,22	92
371,32	102
372,419	98
373,518	109
374,617	121
375,714	139
376,812	181
377,911	213
379,007	290
380,105	395
381,202	458
382,297	448
383,395	397
384,491	272
385,587	166
386,682	129
387,777	100
388,873	88
389,968	84
391,063	89
392,157	82
393,25	90
394,344	89
395,437	89
396,531	99
397,623	108
398,717	128
399,809	140
400,901	186
401,992	226
403,084	330
404,175	454
405,266	658
406,357	894
407,448	928
408,539	788
409,627	536
410,718	325
411,806	202
412,896	153
413,984	122
415,074	116
416,162	113
417,25	94
418,338	101
419,425	95
420,512	96
421,599	86
422,686	94
423,773	82
424,858	90
425,945	92
427,031	83
428,116	72
429,202	82
430,286	84
431,37	81
432,456	87
433,539	87
434,623	86
435,706	84
436,79	90
437,873	93
438,954	87
440,037	88
441,12	86
442,202	95
443,283	92
444,365	105
445,445	92
446,526	102
447,608	109
448,688	114
449,767	108
450,847	109
451,926	106
453,006	111
454,085	104
455,162	103
456,241	98
457,32	100
458,396	90
459,475	98
460,551	102
461,63	94
462,706	97
463,782	90
464,858	90
465,934	90
467,009	82
468,085	78
469,16	77
470,235	76
471,311	74
472,386	64
473,458	66
474,533	65
475,606	61
476,68	62
477,753	54
478,825	54
479,897	57
480,969	54
482,041	62
483,112	54
484,184	56
485,255	60
486,327	63
487,398	56
488,467	64
489,538	52
490,607	60
491,678	64
492,746	59
493,814	55
494,883	54
495,951	61
497,021	62
498,089	62
499,155	60
500,222	58
501,29	56
502,357	58
503,423	58
504,49	62
505,555	58
506,622	61
507,686	52
508,751	60
509,818	58
510,882	64
511,946	60
513,01	62
514,074	59
515,138	58
516,2	56
517,264	60
518,327	60
519,389	56
520,452	64
521,513	66
522,574	59
523,637	59
524,698	63
525,758	63
526,819	59
527,879	63
528,939	65
529,999	62
531,059	59
532,117	65
533,177	48
534,235	56
535,294	66
536,352	58
537,411	64
538,468	63
539,525	58
540,582	66
541,638	57
542,695	54
543,752	65
544,808	56
545,864	60
546,92	62
547,974	62
549,03	58
550,084	75
551,14	64
552,193	69
553,246	64
554,3	72
555,353	64
556,406	64
557,459	67
558,511	70
559,564	67
560,617	77
561,669	72
562,719	76
563,771	71
564,821	70
565,871	79
566,923	86
567,973	77
569,022	78
570,072	80
571,121	73
572,17	71
573,219	76
574,268	73
575,317	64
576,363	71
577,412	70
578,458	72
579,507	73
580,553	80
581,599	68
582,647	67
583,693	71
584,738	76
585,784	78
586,829	75
587,873	67
588,918	74
589,963	74
591,008	78
592,051	76
593,096	74
594,138	75
595,181	80
596,225	74
597,267	80
598,309	77
599,351	72
600,393	72
601,435	75
602,475	69
603,516	72
604,557	68
605,597	72
606,638	76
607,677	66
608,718	65
609,757	59
610,795	60
611,834	52
612,872	65
613,91	62
614,949	62
615,987	70
617,025	63
618,063	57
619,098	67
620,136	62
621,171	63
622,209	66
623,244	63
624,279	68
625,314	59
626,349	58
627,384	60
628,418	62
629,453	64
630,487	61
631,521	63
632,554	70
633,588	60
634,62	61
635,653	54
636,685	62
637,717	62
638,748	62
639,781	62
640,813	61
641,844	57
642,873	51
643,904	55
644,934	57
645,965	56
646,993	55
648,024	56
649,052	55
650,08	48
651,11	54
652,138	50
653,166	52
654,194	55
655,221	55
656,249	47
657,276	40
658,303	55
659,328	52
660,355	46
661,38	53
662,407	51
663,432	47
664,456	56
665,482	53
666,507	47
667,531	50
668,555	53
669,579	54
670,603	48
671,625	50
672,648	58
673,672	56
674,693	51
675,716	52
676,737	47
677,758	52
678,779	59
679,802	54
680,823	50
681,843	55
682,862	50
683,882	50
684,902	49
685,922	50
686,94	48
687,96	55
688,978	59
689,997	51
691,015	52
692,032	50
693,05	56
694,067	57
695,084	59
696,101	47
697,118	55
698,134	57
699,149	46
700,166	53
701,182	53
702,196	54
703,21	53
704,226	59
705,24	64
706,254	55
707,268	54
708,281	51
709,295	49
710,308	55
711,319	59
712,333	59
713,346	57
714,357	59
715,369	53
716,38	63
717,391	61
718,401	50
719,413	61
720,424	59
721,434	50
722,442	57
723,452	60
724,461	53
725,471	58
726,479	61
727,488	63
728,495	60
729,503	56
730,512	57
731,519	62
732,526	62
733,532	56
734,539	63
735,546	65
736,552	58
737,556	60
738,563	64
739,567	66
740,573	65
741,577	67
742,582	64
743,586	64
744,589	64
745,593	71
746,596	56
747,599	64
748,603	58
749,606	64
750,607	70
751,609	54
752,61	70
753,612	61
754,613	70
755,613	71
756,616	63
757,616	70
758,616	68
759,616	56
760,615	58
761,613	65
762,613	60
763,612	55
764,609	60
765,609	56
766,606	64
767,605	61
768,602	59
769,599	62
770,595	54
771,592	59
772,588	60
773,585	56
774,581	57
775,575	58
776,571	56
777,565	52
778,561	54
779,555	59
780,548	63
781,544	62
782,537	65
783,53	63
784,524	51
785,517	59
786,51	61
787,5	57
788,493	56
789,484	57
790,476	52
791,467	60
792,459	59
793,449	52
794,44	57
795,43	52
796,419	50
797,409	55
798,399	47
799,388	58
800,376	53
801,365	52
802,353	55
803,342	50
804,329	54
805,316	63
806,304	54
807,291	57
808,278	55
809,264	56
810,251	54
811,235	50
812,221	59
813,207	63
814,191	61
815,177	60
816,161	61
817,145	63
818,13	54
819,114	58
820,097	50
821,08	60
822,063	52
823,044	53
824,027	58
825,01	52
825,991	58
826,973	57
827,954	58
828,936	42
829,917	50
830,897	49
831,877	50
832,857	60
833,837	52
834,817	55
835,794	54
836,774	46
837,753	56
838,731	48
839,71	48
840,687	56
841,664	55
842,641	56
843,618	62
844,595	53
845,571	54
846,548	44
847,524	51
848,5	51
849,475	53
850,451	58
851,425	49
852,401	53
853,375	54
854,348	53
855,322	53
856,295	48
857,269	50
858,242	53
859,215	52
860,186	51
861,159	54
862,13	54
863,103	46
864,074	48
865,044	48
866,017	48
866,987	53
867,957	59
868,928	53
869,898	55
870,866	51
871,835	56
872,805	54
873,773	53
874,742	53
875,71	56
876,677	54
877,645	50
878,612	58
879,579	48
880,546	56
881,513	44
882,479	53
883,446	51
884,411	47
885,377	60
886,341	51
887,308	59
888,272	54
889,236	51
890,2	54
891,164	48
892,127	57
893,091	52
894,055	53
895,016	44
895,979	52
896,941	49
897,904	53
898,865	51
899,826	54
900,789	46
901,749	50
902,71	53
903,671	51
904,631	56
905,589	52
906,55	54
907,51	48
908,468	53
909,426	52
910,386	56
911,344	57
912,301	50
913,259	48
914,216	50
915,174	51
916,131	52
917,088	47
918,043	50
919	51
919,955	51
920,912	48
921,866	50
922,821	56
923,776	48
924,732	53
925,684	54
926,638	50
927,593	54
928,547	50
929,5	46
930,452	57
931,406	54
932,358	56
933,309	47
934,261	54
935,214	50
936,165	55
937,116	50
938,065	46
939,016	51
939,967	47
940,916	54
941,866	52
942,815	56
943,765	52
944,714	51
945,662	49
946,61	43
947,558	50
948,506	52
949,454	45
950,402	47
951,348	54
952,295	53
953,243	50
954,188	50
955,133	53
956,081	50
957,026	46
957,971	50
958,916	56
959,861	51
960,803	53
961,748	53
962,693	48
963,635	51
964,579	52
965,522	43
966,464	50
967,408	54
968,35	50
969,292	49
970,233	52
971,175	40
972,115	52
973,056	51
973,998	48
974,937	49
975,878	53
976,817	50
977,756	46
978,695	52
979,634	53
980,573	52
981,512	50
982,45	52
983,389	48
984,325	52
985,263	47
986,2	49
987,138	48
988,074	58
989,01	50
989,946	50
990,881	52
991,817	50
992,752	47
993,688	48
994,623	52
995,557	51
996,492	53
997,425	44
998,36	52
999,293	48
1000,23	54
1001,16	52
1002,09	44
1003,02	43
1003,96	51
1004,89	55
1005,82	49
1006,75	49
1007,68	54
1008,61	55
1009,54	54
1010,47	55
1011,4	52
1012,33	54
1013,26	52
1014,19	44
1015,12	49
1016,05	58
1016,98	48
1017,9	53
1018,83	49
1019,76	50
1020,69	45
1021,61	51
1022,54	52
1023,47	45
1024,39	56
1025,32	49
1026,25	47
1027,17	47
1028,1	48
1029,02	52
1029,95	46
1030,87	50
1031,79	50
1032,72	51
1033,64	45
1034,56	45
1035,49	54
1036,41	46
1037,33	47
1038,25	44
1039,18	52
1040,1	48
1041,02	53
1041,94	53
1042,86	47
1043,78	49
1044,7	42
1045,62	52
1046,54	42
1047,46	48
1048,38	46
1049,3	45
1050,22	50
1051,14	53
1052,05	56
1052,97	46
1053,89	49
1054,81	52
1055,72	43
1056,64	46
1057,56	45
1058,47	51
1059,39	48
1060,31	52
1061,22	48
1062,14	52
1063,05	52
1063,97	48
1064,88	52
1065,8	50
1066,71	49
1067,62	46
1068,54	52
1069,45	44
1070,36	53
1071,28	42
1072,19	45
1073,1	53
1074,01	47
1074,92	51
1075,83	48
1076,75	50
1077,66	56
1078,57	38
1079,48	47
1080,39	51
1081,3	55
1082,21	54
1083,12	42
1084,02	52
1084,93	53
1085,84	50
1086,75	45
1087,66	48
1088,56	49
1089,47	45
1090,38	48
1091,29	51
1092,19	51
1093,1	46
1094	47
1094,91	54
1095,81	54
1096,72	54
1097,63	50
1098,53	52
1099,43	50
1100,34	50
1101,24	50
1102,15	48
1103,05	47
1103,95	52
1104,85	46
1105,76	50
1106,66	51
1107,56	51
1108,46	42
1109,36	52
1110,27	44
1111,17	54
1112,07	46
1112,97	55
1113,87	51
1114,77	46
1115,67	52
1116,57	44
1117,46	48
1118,36	53
1119,26	54
1120,16	53
1121,06	50
1121,96	50
1122,85	53
1123,75	51
1124,65	53
1125,55	50
1126,44	48
1127,34	52
1128,23	51
1129,13	51
1130,02	47
1130,92	52
1131,81	52
1132,71	52
1133,6	48
1134,5	54
1135,39	48
1136,28	55
1137,18	48
1138,07	56
1138,96	50
1139,85	51
1140,75	44
1141,64	49
1142,53	48
1143,42	53
1144,31	52
1145,2	47
1146,1	49
1146,98	49
1147,88	52
1148,76	48
1149,65	49
1150,54	46
1151,43	52
1152,32	54
1153,21	55
1154,1	46
1154,98	52
1155,87	51
1156,76	52
1157,65	55
1158,54	50
1159,42	51
1160,31	53
1161,19	51
1162,08	50
1162,97	51
1163,85	48
1164,73	43
1165,62	54
1166,5	55
1167,39	42
1168,27	48
1169,16	57
1170,04	48
1170,92	50
1171,81	47
1172,69	54
1173,57	58
1174,45	49
1175,33	54
1176,21	54
1177,1	55
1177,98	54
1178,86	53
1179,74	48
1180,62	52
1181,5	47
1182,38	54
1183,26	55
1184,14	52
1185,02	54
1185,89	53
1186,77	55
1187,65	49
1188,53	55
1189,41	51
1190,28	49
1191,16	54
1192,04	56
1192,91	47
1193,79	51
1194,67	48
1195,54	54
1196,42	55
1197,29	50
1198,17	56
1199,04	53
1199,92	54