File: RAMAN/MoS2_BM_UP/MoS2-2H (2).txt
#Acq. time (s)=	15
#Accumulations=	3
#Range (cm-¹)=	200...1200
#Windows=	1
#Auto scanning=	Off
#Autofocus=	Off
#AutoExposure=	Off
#Spike filter=	Multiple accum.
#Delay time (s)=	0
#Binning=	1
#Readout mode=	Signal
#DeNoise=	Off
#ICS correction=	Off
#Dark correction=	Off
#Inst. Process=	Off
#Detector Gain=	Best Dynamic Range
#Detector ADC=	45 kHz
#Detector temperature (°C)=	-60,1
#Instrument=	XploRA Plus
#Detector=	Syncerity OE
#Objective=	x50_VIS_LWD
#Grating=	2400 (400nm)
#Filter=	1%
#Laser=	532nm_Edge
#Slit (µm)=	50
#Hole (µm)=	100
#Temperature=	0
#Laser pol=	Circular
#Raman pol=	None
#StageXY=	75x50mm Scan+
#StageZ=	Z motor
#X (µm)=	0
#Y (µm)=	0
#Z (µm)=	251,2
#Full time(s)=	52
#Project=	A
#Sample=	B
#Site=	C
#Title=	D
#Remark=
#Date=	27.09.2024 13:00
#Acquired=	27.09.2024 13:00:15
#AxisType[0]=Intens
#AxisUnit[0]=Cnt
#AxisType[1]=Spectr
#AxisUnit[1]=1/cm
202,268	42
203,409	42
204,547	53
205,687	47
206,825	40
207,965	49
209,103	46
210,241	50
211,378	45
212,516	46
213,653	36
214,79	46
215,927	48
217,064	44
218,2	49
219,337	46
220,471	50
221,607	46
222,743	44
223,877	44
225,011	50
226,146	44
227,28	48
228,413	48
229,548	46
230,681	50
231,814	46
232,947	44
234,08	51
235,21	44
236,342	43
237,475	44
238,607	42
239,736	46
240,868	42
241,998	43
243,129	42
244,258	46
245,39	46
246,519	44
247,647	37
248,776	47
249,905	44
251,033	38
252,161	51
253,29	42
254,418	38
255,543	40
256,671	40
257,799	46
258,924	48
260,051	51
261,177	40
262,304	44
263,428	48
264,553	49
265,678	43
266,802	42
267,926	47
269,05	42
270,174	47
271,298	46
272,422	44
273,546	42
274,667	40
275,79	46
276,914	43
278,035	44
279,157	44
280,278	47
281,399	44
282,519	47
283,641	48
284,762	54
285,882	55
287,001	58
288,121	49
289,239	46
290,358	40
291,478	44
292,597	44
293,714	46
294,833	46
295,949	40
297,068	42
298,184	44
299,301	40
300,417	39
301,533	45
302,651	41
303,767	49
304,88	43
305,996	45
307,111	42
308,226	45
309,341	48
310,454	47
311,569	49
312,682	45
313,796	48
314,909	50
316,021	47
317,135	50
318,247	50
319,359	52
320,47	46
321,582	47
322,693	52
323,804	40
324,913	44
326,024	46
327,135	49
328,244	46
329,355	42
330,463	47
331,573	53
332,681	48
333,789	44
334,899	46
336,007	50
337,115	47
338,222	50
339,329	46
340,437	51
341,542	47
342,648	53
343,755	42
344,86	45
345,966	49
347,071	52
348,177	51
349,281	50
350,385	48
351,491	52
352,594	52
353,698	48
354,801	48
355,904	54
357,008	50
358,109	53
359,211	44
360,314	50
361,415	52
362,517	46
363,619	55
364,72	44
365,82	45
366,921	45
368,021	55
369,121	53
370,22	56
371,32	48
372,419	64
373,518	66
374,617	64
375,714	69
376,812	76
377,911	95
379,007	117
380,105	146
381,202	198
382,297	222
383,395	186
384,491	132
385,587	82
386,682	58
387,777	54
388,873	57
389,968	52
391,063	52
392,157	56
393,25	56
394,344	56
395,437	64
396,531	56
397,623	71
398,717	67
399,809	76
400,901	86
401,992	102
403,084	112
404,175	180
405,266	234
406,357	332
407,448	425
408,539	390
409,627	293
410,718	172
411,806	130
412,896	85
413,984	73
415,074	67
416,162	60
417,25	60
418,338	62
419,425	61
420,512	63
421,599	57
422,686	63
423,773	52
424,858	56
425,945	58
427,031	58
428,116	57
429,202	53
430,286	48
431,37	52
432,456	58
433,539	50
434,623	56
435,706	58
436,79	66
437,873	60
438,954	62
440,037	54
441,12	60
442,202	58
443,283	58
444,365	61
445,445	60
446,526	67
447,608	66
448,688	60
449,767	66
450,847	66
451,926	60
453,006	65
454,085	54
455,162	60
456,241	59
457,32	66
458,396	64
459,475	60
460,551	58
461,63	58
462,706	57
463,782	64
464,858	61
465,934	51
467,009	56
468,085	55
469,16	56
470,235	46
471,311	48
472,386	46
473,458	52
474,533	52
475,606	42
476,68	45
477,753	42
478,825	52
479,897	44
480,969	44
482,041	50
483,112	47
484,184	45
485,255	41
486,327	45
487,398	43
488,467	46
489,538	43
490,607	47
491,678	51
492,746	51
493,814	39
494,883	47
495,951	44
497,021	44
498,089	45
499,155	43
500,222	49
501,29	42
502,357	40
503,423	45
504,49	44
505,555	43
506,622	46
507,686	46
508,751	44
509,818	43
510,882	44
511,946	47
513,01	45
514,074	44
515,138	45
516,2	45
517,264	46
518,327	41
519,389	44
520,452	52
521,513	46
522,574	44
523,637	47
524,698	48
525,758	43
526,819	48
527,879	44
528,939	48
529,999	42
531,059	42
532,117	43
533,177	42
534,235	46
535,294	42
536,352	44
537,411	51
538,468	47
539,525	44
540,582	43
541,638	48
542,695	49
543,752	52
544,808	44
545,864	40
546,92	43
547,974	53
549,03	42
550,084	46
551,14	48
552,193	50
553,246	49
554,3	41
555,353	48
556,406	40
557,459	46
558,511	47
559,564	57
560,617	49
561,669	46
562,719	54
563,771	53
564,821	55
565,871	50
566,923	44
567,973	56
569,022	50
570,072	45
571,121	52
572,17	49
573,219	50
574,268	54
575,317	48
576,363	51
577,412	49
578,458	56
579,507	53
580,553	56
581,599	52
582,647	48
583,693	50
584,738	54
585,784	54
586,829	53
587,873	52
588,918	54
589,963	57
591,008	44
592,051	50
593,096	50
594,138	50
595,181	49
596,225	54
597,267	48
598,309	59
599,351	56
600,393	50
601,435	49
602,475	46
603,516	50
604,557	38
605,597	47
606,638	46
607,677	44
608,718	42
609,757	47
610,795	49
611,834	50
612,872	50
613,91	45
614,949	54
615,987	42
617,025	50
618,063	42
619,098	44
620,136	52
621,171	44
622,209	42
623,244	45
624,279	45
625,314	40
626,349	46
627,384	42
628,418	44
629,453	46
630,487	44
631,521	44
632,554	43
633,588	45
634,62	49
635,653	48
636,685	46
637,717	44
638,748	42
639,781	46
640,813	48
641,844	50
642,873	45
643,904	42
644,934	47
645,965	49
646,993	41
648,024	34
649,052	49
650,08	48
651,11	39
652,138	44
653,166	48
654,194	40
655,221	45
656,249	44
657,276	45
658,303	49
659,328	41
660,355	45
661,38	46
662,407	39
663,432	42
664,456	45
665,482	48
666,507	44
667,531	42
668,555	39
669,579	46
670,603	47
671,625	40
672,648	43
673,672	42
674,693	46
675,716	40
676,737	43
677,758	42
678,779	44
679,802	42
680,823	42
681,843	46
682,862	45
683,882	44
684,902	47
685,922	48
686,94	49
687,96	45
688,978	41
689,997	44
691,015	42
692,032	38
693,05	46
694,067	49
695,084	38
696,101	43
697,118	41
698,134	48
699,149	44
700,166	49
701,182	45
702,196	42
703,21	41
704,226	42
705,24	43
706,254	38
707,268	43
708,281	47
709,295	42
710,308	41
711,319	42
712,333	38
713,346	44
714,357	45
715,369	40
716,38	40
717,391	44
718,401	41
719,413	50
720,424	48
721,434	43
722,442	47
723,452	40
724,461	49
725,471	47
726,479	46
727,488	44
728,495	53
729,503	45
730,512	45
731,519	44
732,526	45
733,532	46
734,539	49
735,546	43
736,552	46
737,556	46
738,563	46
739,567	50
740,573	46
741,577	49
742,582	48
743,586	45
744,589	54
745,593	46
746,596	47
747,599	52
748,603	48
749,606	53
750,607	53
751,609	52
752,61	48
753,612	47
754,613	52
755,613	45
756,616	54
757,616	51
758,616	53
759,616	48
760,615	46
761,613	45
762,613	45
763,612	45
764,609	48
765,609	40
766,606	44
767,605	46
768,602	45
769,599	53
770,595	46
771,592	44
772,588	46
773,585	48
774,581	43
775,575	46
776,571	42
777,565	47
778,561	48
779,555	45
780,548	50
781,544	48
782,537	44
783,53	40
784,524	45
785,517	47
786,51	43
787,5	46
788,493	41
789,484	44
790,476	43
791,467	52
792,459	42
793,449	51
794,44	46
795,43	40
796,419	42
797,409	48
798,399	45
799,388	45
800,376	45
801,365	42
802,353	41
803,342	49
804,329	49
805,316	42
806,304	46
807,291	48
808,278	46
809,264	51
810,251	45
811,235	43
812,221	45
813,207	51
814,191	47
815,177	46
816,161	47
817,145	42
818,13	48
819,114	46
820,097	46
821,08	46
822,063	48
823,044	48
824,027	47
825,01	47
825,991	48
826,973	44
827,954	38
828,936	47
829,917	39
830,897	44
831,877	44
832,857	42
833,837	45
834,817	43
835,794	44
836,774	42
837,753	37
838,731	45
839,71	46
840,687	44
841,664	41
842,641	53
843,618	52
844,595	40
845,571	49
846,548	42
847,524	47
848,5	38
849,475	44
850,451	41
851,425	45
852,401	43
853,375	43
854,348	46
855,322	42
856,295	38
857,269	46
858,242	41
859,215	46
860,186	38
861,159	44
862,13	50
863,103	45
864,074	46
865,044	46
866,017	50
866,987	36
867,957	44
868,928	40
869,898	48
870,866	42
871,835	49
872,805	44
873,773	41
874,742	45
875,71	45
876,677	40
877,645	36
878,612	36
879,579	38
880,546	54
881,513	48
882,479	43
883,446	45
884,411	42
885,377	50
886,341	41
887,308	46
888,272	39
889,236	40
890,2	46
891,164	43
892,127	38
893,091	46
894,055	41
895,016	46
895,979	44
896,941	44
897,904	46
898,865	46
899,826	46
900,789	48
901,749	41
902,71	43
903,671	49
904,631	47
905,589	41
906,55	43
907,51	40
908,468	48
909,426	46
910,386	46
911,344	40
912,301	40
913,259	48
914,216	39
915,174	45
916,131	43
917,088	45
918,043	45
919	39
919,955	46
920,912	45
921,866	42
922,821	39
923,776	47
924,732	39
925,684	44
926,638	43
927,593	34
928,547	44
929,5	44
930,452	50
931,406	46
932,358	44
933,309	46
934,261	43
935,214	41
936,165	55
937,116	48
938,065	41
939,016	42
939,967	36
940,916	45
941,866	43
942,815	44
943,765	50
944,714	41
945,662	42
946,61	45
947,558	45
948,506	42
949,454	48
950,402	43
951,348	48
952,295	46
953,243	40
954,188	45
955,133	46
956,081	39
957,026	42
957,971	44
958,916	44
959,861	48
960,803	43
961,748	41
962,693	40
963,635	43
964,579	42
965,522	45
966,464	41
967,408	44
968,35	48
969,292	46
970,233	36
971,175	45
972,115	42
973,056	44
973,998	40
974,937	44
975,878	47
976,817	42
977,756	39
978,695	43
979,634	42
980,573	41
981,512	44
982,45	49
983,389	42
984,325	44
985,263	45
986,2	43
987,138	44
988,074	45
989,01	45
989,946	44
990,881	45
991,817	46
992,752	44
993,688	42
994,623	38
995,557	43
996,492	44
997,425	46
998,36	45
999,293	47
1000,23	38
1001,16	46
1002,09	43
1003,02	38
1003,96	41
1004,89	41
1005,82	44
1006,75	44
1007,68	41
1008,61	39
1009,54	42
1010,47	42
1011,4	42
1012,33	44
1013,26	38
1014,19	42
1015,12	45
1016,05	42
1016,98	49
1017,9	44
1018,83	46
1019,76	45
1020,69	41
1021,61	48
1022,54	44
1023,47	45
1024,39	44
1025,32	45
1026,25	38
1027,17	42
1028,1	45
1029,02	46
1029,95	44
1030,87	44
1031,79	50
1032,72	46
1033,64	46
1034,56	42
1035,49	44
1036,41	44
1037,33	50
1038,25	48
1039,18	40
1040,1	44
1041,02	45
1041,94	47
1042,86	42
1043,78	41
1044,7	39
1045,62	37
1046,54	40
1047,46	42
1048,38	41
1049,3	42
1050,22	43
1051,14	47
1052,05	38
1052,97	38
1053,89	51
1054,81	37
1055,72	49
1056,64	40
1057,56	41
1058,47	44
1059,39	43
1060,31	40
1061,22	46
1062,14	39
1063,05	43
1063,97	44
1064,88	42
1065,8	44
1066,71	43
1067,62	41
1068,54	45
1069,45	38
1070,36	42
1071,28	42
1072,19	41
1073,1	42
1074,01	46
1074,92	40
1075,83	42
1076,75	42
1077,66	44
1078,57	50
1079,48	46
1080,39	44
1081,3	44
1082,21	44
1083,12	43
1084,02	46
1084,93	38
1085,84	40
1086,75	41
1087,66	40
1088,56	40
1089,47	44
1090,38	41
1091,29	45
1092,19	42
1093,1	45
1094	40
1094,91	45
1095,81	44
1096,72	46
1097,63	47
1098,53	47
1099,43	46
1100,34	40
1101,24	45
1102,15	38
1103,05	40
1103,95	47
1104,85	44
1105,76	46
1106,66	43
1107,56	48
1108,46	43
1109,36	43
1110,27	49
1111,17	43
1112,07	38
1112,97	44
1113,87	42
1114,77	41
1115,67	46
1116,57	44
1117,46	42
1118,36	44
1119,26	48
1120,16	44
1121,06	42
1121,96	50
1122,85	40
1123,75	46
1124,65	46
1125,55	44
1126,44	48
1127,34	40
1128,23	41
1129,13	41
1130,02	45
1130,92	39
1131,81	43
1132,71	47
1133,6	46
1134,5	49
1135,39	49
1136,28	46
1137,18	45
1138,07	47
1138,96	46
1139,85	46
1140,75	42
1141,64	47
1142,53	52
1143,42	44
1144,31	46
1145,2	43
1146,1	39
1146,98	44
1147,88	40
1148,76	44
1149,65	47
1150,54	44
1151,43	44
1152,32	40
1153,21	42
1154,1	44
1154,98	47
1155,87	45
1156,76	47
1157,65	52
1158,54	43
1159,42	43
1160,31	44
1161,19	41
1162,08	48
1162,97	52
1163,85	40
1164,73	45
1165,62	48
1166,5	44
1167,39	42
1168,27	44
1169,16	45
1170,04	48
1170,92	48
1171,81	36
1172,69	47
1173,57	53
1174,45	48
1175,33	49
1176,21	42
1177,1	44
1177,98	50
1178,86	50
1179,74	46
1180,62	43
1181,5	46
1182,38	45
1183,26	47
1184,14	42
1185,02	51
1185,89	40
1186,77	47
1187,65	43
1188,53	47
1189,41	51
1190,28	44
1191,16	38
1192,04	40
1192,91	50
1193,79	40
1194,67	56
1195,54	47
1196,42	44
1197,29	48
1198,17	47
1199,04	52
1199,92	46